Workbook

Sheet Disclaimer
B4: ="Project: "&Cockpit!C4 -> Project: Template
B6: Status: Working Draft
B9: Databook Financial Due Diligence
B11: BakerTilly, #city#date#
B14: Disclaimer: This Databook is confidential and has been prepared exclusively for the benefit of the Client in connection with the Transaction and may not be disclosed, quoted, used or relied on for any other purpose or by any other party than the Client without the prior written consent of BT. This Databook is made available to the Client and we consent to the disclosure, provided that the client agress to non-reliance of this work-in-progress databook. Compensation claims of the Purchaser against BT for damages caused by negligence in connection with performance of the assignment are limited to EUR 4.000.000 (in words: Euro four million) for each damage event and for all damage events in total.

Sheet Cockpit
B3: Table labels | G3: =user input -> #VALUE!
B4: Project name | C4: Template
B5: Currency base code | C5: EUR | G5: =technische hilfszelle --> nicht löschen -> #VALUE!
B7: Quelle: | C7: Datenraum/ eigene Analysen
B8: Source: | C8: Virtual Data Room/ Company Information
B10: Working Group
B11: Partner
B12: Manager
B13: Senior/Assistant
B16: Timeline parameter
B17: End of first historical period | C17: 44926
B18: Number of historical periods | C18: 3
B19: Label | C19: IST | D19: Adjust according to language(DEU/ ENG)
B21: CYT Begin Date | C21: 45658 | D21: =IF(C21<(EDATE(C17,24)),"CYT Begin Date must not be prior to historical date","ok") -> ok
B22: CYT Date | C22: 45808 | D22: =IF(TEXT($C$22,"TT.MM.")="31.12.","CYT date must not be December 31, check","ok") -> ok
B23: Label (Last twelve months) | C23: LTM
B24: Label (Current year trading) | C24: YTD
B25: Label (Year to go) | C25: YTG
B27: Label | C27: Plan
B31: Timeline (annual for PL and CF)
B32: Counter | D32: 1 | E32: =D32+1 -> 2 | F32: =E32+1 -> 3 | G32: =F32+1 -> 4 | H32: =G32+1 -> 5 | I32: =H32+1 -> 6 | J32: =I32+1 -> 7 | K32: =J32+1 -> 8 | L32: =K32+1 -> 9
B33: Date (Auto) | C33: =EDATE($C$17,-12) -> 44561 | D33: =IF(D$32<$C$18+1,EDATE($C$33,12*D$32),IF(OR(D$32=$C$18+1,D$32=$C$18+2),$C$22,IF(D$32>$C$18+2,EDATE($C$33,(D$32-2)*12)))) -> 44926 | E33: =IF(E$32<$C$18+1,EDATE($C$33,12*E$32),IF(OR(E$32=$C$18+1,E$32=$C$18+2),$C$22,IF(E$32>$C$18+2,EDATE($C$33,(E$32-2)*12)))) -> 45291 | F33: =IF(F$32<$C$18+1,EDATE($C$33,12*F$32),IF(OR(F$32=$C$18+1,F$32=$C$18+2),$C$22,IF(F$32>$C$18+2,EDATE($C$33,(F$32-2)*12)))) -> 45657 | G33: =IF(G$32<$C$18+1,EDATE($C$33,12*G$32),IF(OR(G$32=$C$18+1,G$32=$C$18+2),$C$22,IF(G$32>$C$18+2,EDATE($C$33,(G$32-2)*12)))) -> 45808 | H33: =IF(H$32<$C$18+1,EDATE($C$33,12*H$32),IF(OR(H$32=$C$18+1,H$32=$C$18+2),$C$22,IF(H$32>$C$18+2,EDATE($C$33,(H$32-2)*12)))) -> 45808 | I33: =IF(I$32<$C$18+1,EDATE($C$33,12*I$32),IF(OR(I$32=$C$18+1,I$32=$C$18+2),$C$22,IF(I$32>$C$18+2,EDATE($C$33,(I$32-2)*12)))) -> 46022 | J33: =IF(J$32<$C$18+1,EDATE($C$33,12*J$32),IF(OR(J$32=$C$18+1,J$32=$C$18+2),$C$22,IF(J$32>$C$18+2,EDATE($C$33,(J$32-2)*12)))) -> 46387 | K33: =IF(K$32<$C$18+1,EDATE($C$33,12*K$32),IF(OR(K$32=$C$18+1,K$32=$C$18+2),$C$22,IF(K$32>$C$18+2,EDATE($C$33,(K$32-2)*12)))) -> 46752 | L33: =IF(L$32<$C$18+1,EDATE($C$33,12*L$32),IF(OR(L$32=$C$18+1,L$32=$C$18+2),$C$22,IF(L$32>$C$18+2,EDATE($C$33,(L$32-2)*12)))) -> 47118
B34: Label | C34: =$C$19 -> IST | D34: =IF(D$32<=$C$18,$C$19,IF(D$32=$C$18+1,$C$23,IF(D$32=$C$18+2,$C$24,$C$27))) -> IST | E34: =IF(E$32<=$C$18,$C$19,IF(E$32=$C$18+1,$C$23,IF(E$32=$C$18+2,$C$24,$C$27))) -> IST | F34: =IF(F$32<=$C$18,$C$19,IF(F$32=$C$18+1,$C$23,IF(F$32=$C$18+2,$C$24,$C$27))) -> IST | G34: =IF(G$32<=$C$18,$C$19,IF(G$32=$C$18+1,$C$23,IF(G$32=$C$18+2,$C$24,$C$27))) -> LTM | H34: =IF(H$32<=$C$18,$C$19,IF(H$32=$C$18+1,$C$23,IF(H$32=$C$18+2,$C$24,$C$27))) -> YTD | I34: =IF(I$32<=$C$18,$C$19,IF(I$32=$C$18+1,$C$23,IF(I$32=$C$18+2,$C$24,$C$27))) -> Plan | J34: =IF(J$32<=$C$18,$C$19,IF(J$32=$C$18+1,$C$23,IF(J$32=$C$18+2,$C$24,$C$27))) -> Plan | K34: =IF(K$32<=$C$18,$C$19,IF(K$32=$C$18+1,$C$23,IF(K$32=$C$18+2,$C$24,$C$27))) -> Plan | L34: =IF(L$32<=$C$18,$C$19,IF(L$32=$C$18+1,$C$23,IF(L$32=$C$18+2,$C$24,$C$27))) -> Plan
B37: Timeline (annual for BS)
B38: Counter | D38: 1 | E38: =D38+1 -> 2 | F38: =E38+1 -> 3 | G38: =F38+1 -> 4 | H38: =G38+1 -> 5 | I38: =H38+1 -> 6 | J38: =I38+1 -> 7 | K38: =J38+1 -> 8
B39: Date | C39: =EDATE($C$17,-12) -> 44561 | D39: =IF(D$38<$C$18+1,EDATE($C$39,12*D$38),IF(D$38=$C$18+1,$C$22,IF(D$38>$C$18+1,EDATE($C$39,(D$38-1)*12)))) -> 44926 | E39: =IF(E$38<$C$18+1,EDATE($C$39,12*E$38),IF(E$38=$C$18+1,$C$22,IF(E$38>$C$18+1,EDATE($C$39,(E$38-1)*12)))) -> 45291 | F39: =IF(F$38<$C$18+1,EDATE($C$39,12*F$38),IF(F$38=$C$18+1,$C$22,IF(F$38>$C$18+1,EDATE($C$39,(F$38-1)*12)))) -> 45657 | G39: =IF(G$38<$C$18+1,EDATE($C$39,12*G$38),IF(G$38=$C$18+1,$C$22,IF(G$38>$C$18+1,EDATE($C$39,(G$38-1)*12)))) -> 45808 | H39: =IF(H$38<$C$18+1,EDATE($C$39,12*H$38),IF(H$38=$C$18+1,$C$22,IF(H$38>$C$18+1,EDATE($C$39,(H$38-1)*12)))) -> 46022 | I39: =IF(I$38<$C$18+1,EDATE($C$39,12*I$38),IF(I$38=$C$18+1,$C$22,IF(I$38>$C$18+1,EDATE($C$39,(I$38-1)*12)))) -> 46387 | J39: =IF(J$38<$C$18+1,EDATE($C$39,12*J$38),IF(J$38=$C$18+1,$C$22,IF(J$38>$C$18+1,EDATE($C$39,(J$38-1)*12)))) -> 46752 | K39: =IF(K$38<$C$18+1,EDATE($C$39,12*K$38),IF(K$38=$C$18+1,$C$22,IF(K$38>$C$18+1,EDATE($C$39,(K$38-1)*12)))) -> 47118
B40: Label | C40: =$C$19 -> IST | D40: =IF(D$38<=$C$18,$C$19,IF(D$38=$C$18+1,$C$19,$C$27)) -> IST | E40: =IF(E$38<=$C$18,$C$19,IF(E$38=$C$18+1,$C$19,$C$27)) -> IST | F40: =IF(F$38<=$C$18,$C$19,IF(F$38=$C$18+1,$C$19,$C$27)) -> IST | G40: =IF(G$38<=$C$18,$C$19,IF(G$38=$C$18+1,$C$19,$C$27)) -> IST | H40: =IF(H$38<=$C$18,$C$19,IF(H$38=$C$18+1,$C$19,$C$27)) -> Plan | I40: =IF(I$38<=$C$18,$C$19,IF(I$38=$C$18+1,$C$19,$C$27)) -> Plan | J40: =IF(J$38<=$C$18,$C$19,IF(J$38=$C$18+1,$C$19,$C$27)) -> Plan | K40: =IF(K$38<=$C$18,$C$19,IF(K$38=$C$18+1,$C$19,$C$27)) -> Plan
B43: Timeline (monthly)
B44: Counter | D44: 1 | E44: =D44+1 -> 2 | F44: =E44+1 -> 3 | G44: =F44+1 -> 4 | H44: =G44+1 -> 5 | I44: =H44+1 -> 6 | J44: =I44+1 -> 7 | K44: =J44+1 -> 8 | L44: =K44+1 -> 9 | ... CI44: =CH44+1 -> 84
B45: Date | C45: =EDATE($C$17,-12) -> 44561 | D45: =EDATE($C$45,D$44) -> 44592 | E45: =EDATE($C$45,E$44) -> 44620 | F45: =EDATE($C$45,F$44) -> 44651 | G45: =EDATE($C$45,G$44) -> 44681 | H45: =EDATE($C$45,H$44) -> 44712 | I45: =EDATE($C$45,I$44) -> 44742 | J45: =EDATE($C$45,J$44) -> 44773 | K45: =EDATE($C$45,K$44) -> 44804 | ... CI45: =EDATE($C$45,CI$44) -> 47118
B46: Label | C46: =$C$19 -> IST | D46: =IF(D$45<=$C$22,$C$19,$C$27) -> IST | E46: =IF(E$45<=$C$22,$C$19,$C$27) -> IST | F46: =IF(F$45<=$C$22,$C$19,$C$27) -> IST | G46: =IF(G$45<=$C$22,$C$19,$C$27) -> IST | H46: =IF(H$45<=$C$22,$C$19,$C$27) -> IST | I46: =IF(I$45<=$C$22,$C$19,$C$27) -> IST | J46: =IF(J$45<=$C$22,$C$19,$C$27) -> IST | K46: =IF(K$45<=$C$22,$C$19,$C$27) -> IST | ... CI46: =IF(CI$45<=$C$22,$C$19,$C$27) -> Plan

Sheet Mastersheet
A1: Konto | B1: Bezeichnung | C1: Klasse | D1: NA-Zeile | E1: Review | F1: P1 | G1: P2 | H1: P3 | I1: P4 | J1: P5 | K1: P6 | L1: P7 | M1: P8 | N1: P9 | O1: P10
B2: <Mastersheet wird je Mandat aus der SuSa befuellt. Spalten F bis O sind die Perioden in EUR.>

Sheet Datengrundlage
B2: Deutsch: | F2: Manuell Anpassen | H2: Englisch: | L2: Manuell Anpassen
B3: =Cockpit!$C$4 -> Template | C3: =Cockpit!D33 -> 44926 | D3: =Cockpit!E33 -> 45291 | E3: =Cockpit!F33 -> 45657 | F3: YTD Jan23 | H3: =Cockpit!$C$4 -> Template | I3: =Cockpit!D33 -> 44926 | J3: =Cockpit!E33 -> 45291 | K3: =Cockpit!F33 -> 45657 | L3: YTD Jan23
B6: Entity 1 | H6: Entity 1 | M6: Manuell Anpassen
B7: Jahresabschlüsse (ungeprüft) | C7: ja | D7: ja | E7: ja | F7: - | H7: Annual reports (unaudited) | I7: yes | J7: yes | K7: yes | L7: - | M7: Manuell Anpassen
B8: Summen- und Saldenlisten (SuSas) - monatlich | C8: ja | D8: ja | E8: ja | F8: ja | H8: Monthly trial balances | I8: yes | J8: yes | K8: yes | L8: yes
B9: Betriebswirtschaftliche Auswertungen (BWAs) - monatlich | C9: ja | D9: ja | E9: ja | F9: ja | H9: Revenue data and selected KPIs | I9: yes | J9: yes | K9: yes | L9: yes
B10: Umsatzdaten und ausgewählte KPIs | C10: ja | D10: ja | E10: ja | F10: ja | H10: Detailed analyes and managerial accounting reports | I10: - | J10: - | K10: - | L10: -
B11: Detailaufrisse und Controlling-/ERP-Auswertungen | C11: - | D11: - | E11: - | F11: - | H11: Further details on selected topics | J11: yes
B12: Weitere Auskünfte zu ausgewählten Sachverhalten | D12: ja
B14: Entity 2 | H14: Entity 2 | M14: Manuell Anpassen
B15: Jahresabschlüsse (ungeprüft) | C15: ja | D15: ja | E15: ja | F15: - | H15: Annual reports (unaudited) | I15: yes | J15: yes | K15: yes | L15: -
B16: Summen- und Saldenlisten (SuSas) - monatlich | C16: ja | D16: ja | E16: ja | F16: ja | H16: Monthly trial balances | I16: yes | J16: yes | K16: yes | L16: yes
B17: Betriebswirtschaftliche Auswertungen (BWAs) - monatlich | C17: ja | D17: ja | E17: ja | F17: ja | H17: Revenue data and selected KPIs | I17: yes | J17: yes | K17: yes | L17: yes
B18: Umsatzdaten und ausgewählte KPIs | C18: ja | D18: ja | E18: ja | F18: ja | H18: Detailed analyes and managerial accounting reports | I18: - | J18: - | K18: - | L18: -
B19: Detailaufrisse und Controlling-/ERP-Auswertungen | C19: - | D19: - | E19: - | F19: - | H19: Further details on selected topics | J19: yes
B20: Weitere Auskünfte zu ausgewählten Sachverhalten | D20: ja
B22: Entity 3 | H22: Entity 3 | M22: Manuell Anpassen
B23: Jahresabschlüsse (ungeprüft) | C23: ja | D23: ja | E23: ja | F23: - | H23: Annual reports (unaudited) | I23: yes | J23: yes | K23: yes | L23: -
B24: Summen- und Saldenlisten (SuSas) - monatlich | C24: ja | D24: ja | E24: ja | F24: ja | H24: Monthly trial balances | I24: yes | J24: yes | K24: yes | L24: yes
B25: Betriebswirtschaftliche Auswertungen (BWAs) - monatlich | C25: ja | D25: ja | E25: ja | F25: ja | H25: Revenue data and selected KPIs | I25: yes | J25: yes | K25: yes | L25: yes
B26: Umsatzdaten und ausgewählte KPIs | C26: ja | D26: ja | E26: ja | F26: ja | H26: Detailed analyes and managerial accounting reports | I26: - | J26: - | K26: - | L26: -
B27: Detailaufrisse und Controlling-/ERP-Auswertungen | C27: - | D27: - | E27: - | F27: - | H27: Further details on selected topics | J27: yes
B28: Weitere Auskünfte zu ausgewählten Sachverhalten | D28: ja
B30: Entity 4 | H30: Entity 4 | M30: Manuell Anpassen
B31: Jahresabschlüsse (ungeprüft) | C31: ja | D31: ja | E31: ja | F31: - | H31: Annual reports (unaudited) | I31: yes | J31: yes | K31: yes | L31: -
B32: Summen- und Saldenlisten (SuSas) - monatlich | C32: ja | D32: ja | E32: ja | F32: ja | H32: Monthly trial balances | I32: yes | J32: yes | K32: yes | L32: yes
B33: Betriebswirtschaftliche Auswertungen (BWAs) - monatlich | C33: ja | D33: ja | E33: ja | F33: ja | H33: Revenue data and selected KPIs | I33: yes | J33: yes | K33: yes | L33: yes
B34: Umsatzdaten und ausgewählte KPIs | C34: ja | D34: ja | E34: ja | F34: ja | H34: Detailed analyes and managerial accounting reports | I34: - | J34: - | K34: - | L34: -
B35: Detailaufrisse und Controlling-/ERP-Auswertungen | C35: - | D35: - | E35: - | F35: - | H35: Further details on selected topics | J35: yes
B36: Weitere Auskünfte zu ausgewählten Sachverhalten | D36: ja
B38: ="Quelle: "&Cockpit!$C$7 -> Quelle: Datenraum/ eigene Analysen | H38: ="Source: "&Cockpit!$C$8 -> Source: Virtual Data Room/ Company Information

Sheet Abkürzungsverzeichnis
A1: Deutsch | C1: kurz | D1: Lang | F1: English | H1: short | I1: long
A2: 1 | C2: Adj. | D2: Angepasst | F2: 1 | H2: Act. | I2: Actual figures
A3: 2 | C3: AO | D3: Abgabenordnung | F3: 2 | H3: Adj. | I3: Adjusted
A4: 3 | C4: BP | D4: Betriebsprüfung | F4: 3 | H4: BoP | I4: Beginning of period
A5: 4 | C5: BT | D5: Baker Tilly | F5: 4 | H5: BT | I5: Baker Tilly
A6: 5 | C6: BWA | D6: Betriebswirtschaftliche Auswertung | F6: 5 | H6: c. | I6: circa
A7: 6 | C7: ca. | D7: circa | F7: 6 | H7: CAGR | I7: Compounded Annual Growth Rate
A8: 7 | C8: CAGR | D8: Compounded Annual Growth Rate | F8: 7 | H8: CAPEX | I8: Capital Expenditures
A9: 8 | C9: CAPEX | D9: Capital Expenditures | F9: 8 | H9: CCC | I9: Cash Conversion Cycle
A10: 9 | C10: CCC | D10: Cash Conversion Cycle | F10: 9 | H10: CDD | I10: Commercial Due Diligence
A11: 10 | C11: CDD | D11: Commercial Due Diligence | F11: 10 | H11: CLI | I11: Cash-like item
A12: 11 | C12: DIO | D12: Lagerdauer | F12: 11 | H12: COGS | I12: Cost of Goods sold
A13: 12 | C13: DPO | D13: Kreditorenlaufzeit | F13: 12 | H13: cont'd | I13: continued
... A21: 20 | C21: FTE | D21: Full-Time Equivalent | F21: 20 | H21: EoP | I21: End of period
A22: 21 | B22: Spalte 1 | C22: GewSt | D22: Gewerbesteuer | F22: 21 | G22: Spalte 1 | H22: EOY | I22: End of year
A23: 1 | C23: GJ | D23: Geschäftsjahr | F23: 1 | H23: EUR | I23: Euro
A24: 2 | C24: GmbH | D24: Gesellschaft mit beschränkter Haftung | F24: 2 | H24: FC | I24: Forecast
A25: 3 | C25: h | D25: Stunde | F25: 3 | H25: FDD | I25: Financial Due Diligence
A26: 4 | C26: HGB | D26: Handelsgesetzbuch | F26: 4 | H26: FTE | I26: Full-Time Equivalent
A27: 5 | C27: i.d.R. | D27: in der Regel | F27: 5 | H27: FX | I27: Foreign exchange
A28: 6 | C28: i.H.v. | D28: in Höhe von | F28: 6 | H28: FY | I28: Fiscal year
A29: 7 | C29: KSt | D29: Körperschaftsteuer | F29: 7 | H29: GmbH | I29: Limited Company
A30: 8 | C30: KStG | D30: Körperschaftsteuergesetz | F30: 8 | H30: h | I30: hour
A31: 9 | C31: L.u.L. | D31: Lieferungen und Leistungen | F31: 9 | H31: HGB | I31: German Commercial Code
A32: 10 | C32: LTM | D32: Last Twelve Months | F32: 10 | H32: kEUR | I32: Thousand Euro
A33: 11 | C33: p.a. | D33: per annum, jährlich | F33: 11 | H33: LTM | I33: Last Twelve Months
A34: 12 | C34: PPA | D34: Purchase Price Allocation | F34: 12 | H34: OOI | I34: Other operating income
... A42: 20 | C42: SuSa | D42: Summen- und Saldenliste | F42: 20 | H42: SuSa | I42: Trial balance
A43: 21 | B43: Spalte 2 | C43: TDD | D43: Tax Due Diligence | F43: 21 | G43: Spalte 2 | H43: TDD | I43: Tax Due Diligence
A44: 1 | C44: TEUR | D44: Tausend Euro | F44: 1 | H44: TWC | I44: Trade Working Capital
A45: 2 | C45: TWC | D45: Trade Working Capital | F45: 2 | H45: USD | I45: US Dollar
A46: 3 | C46: USD | D46: US Dollar | F46: 3 | H46: VDR | I46: Virtual Dataroom
A47: 4 | C47: USt | D47: Umsatzsteuer | F47: 4 | H47: WIP | I47: Work-in-Progress
A48: 5 | C48: VdN | D48: Vorbehalt der Nachprüfung | F48: 5 | H48: YoY | I48: Year-on-Year
A49: 6 | C49: VDR | D49: Datenraum | F49: 6 | H49: YTD | I49: Year-to-Date
A50: 7 | C50: WIP | D50: Work-in-Progress | F50: 7 | H50: YTG | I50: Year-to-Go
A51: 8 | C51: WJ | D51: Wirtschaftsjahr | F51: 8
A52: 9 | C52: YTD | D52: Year-to-Date | F52: 9
A53: 10 | C53: YTG | D53: Year-to-Go | F53: 10
A54: 11 | C54: AHK | D54: Anschaffungs- und Herstellungskosten | F54: 11
...

Sheet Think Cell
A2: Revenue Split
B4: ='Lead PL'!F6 -> 44926 | E4: ='Lead PL'!G6 -> 45291 | H4: ='Lead PL'!H6 -> 45657 | K4: ='Lead PL'!I6 -> 45808
A5: Dummy 1
A6: Dummy 2
A7: Dummy 3
A8: Dummy 4
A13: Total Output and EBITDA
B17: ='Lead PL'!F6 -> 44926 | C17: ='Lead PL'!G6 -> 45291 | D17: ='Lead PL'!H6 -> 45657 | E17: ='Lead PL'!I6 -> 45808
B18: FY | C18: FY | D18: FY | E18: LTM
A19: EBITDA-margin (normalized) | B19: =PL_QoE!F44 -> n/a | C19: =PL_QoE!G44 -> n/a | D19: =PL_QoE!H44 -> n/a | E19: =PL_QoE!I44 -> n/a
A20: EBITDA-margin | B20: =PL_QoE!F41 -> n/a | C20: =PL_QoE!G41 -> n/a | D20: =PL_QoE!H41 -> n/a | E20: =PL_QoE!I41 -> n/a
A21: Total Output | B21: ='Lead PL'!F39 -> 0 | C21: ='Lead PL'!G39 -> 0 | D21: ='Lead PL'!H39 -> 0 | E21: ='Lead PL'!I39 -> 0
A22: EBITDA | B22: ='Lead PL'!F146 -> 0 | C22: ='Lead PL'!G146 -> 0 | D22: ='Lead PL'!H146 -> 0 | E22: ='Lead PL'!I146 -> 0
A23: Adj. EBITDA | B23: =PL_QoE!F30 -> 0 | C23: =PL_QoE!G30 -> 0 | D23: =PL_QoE!H30 -> 0 | E23: =PL_QoE!I30 -> 0
A28: EBITDA-Bridge
B31: ="EBITDA FY" & RIGHT(YEAR(Cockpit!D33),2) & " Act." -> EBITDA FY22 Act. | C31: ="∆ "&'Lead PL'!D9 -> ∆ Revenues | D31: ="∆ "&'Lead PL'!D18 -> ∆ Change in inventory | E31: ="∆ "&'Lead PL'!D27 -> ∆ Own work capitalized | F31: ="∆ "&'Lead PL'!D36 -> ∆ Dummy 1 | G31: ="∆ "&'Lead PL'!D37 -> ∆ Dummy 2 | H31: ="∆ "&'Lead PL'!D38 -> ∆ Dummy 3 | I31: ="∆ "&'Lead PL'!D40 -> ∆ Cost of materials | J31: ="∆ "&'Lead PL'!D53 -> ∆ Personnel expenses | K31: ="∆ "&'Lead PL'!D62 -> ∆ Premise costs | L31: ="∆ "&'Lead PL'!D71 -> ∆ Repair and maintenance | M31: ="∆ "&'Lead PL'!D80 -> ∆ Sales costs | N31: ="∆ "&'Lead PL'!D89 -> ∆ Delivery costs | O31: ="∆ "&'Lead PL'!D98 -> ∆ Vehicle costs | P31: ="∆ "&'Lead PL'!D107 -> ∆ Insurance, contributions and levies expenses | Q31: ="∆ "&'Lead PL'!D116 -> ∆ Advertising and travel expenses | R31: ="∆ "&'Lead PL'!D125 -> ∆ Other operating income | S31: ="∆ "&'Lead PL'!D134 -> ∆ Other operating expenses | T31: ="∆ "&'Lead PL'!D143 -> ∆ Dummy 1 | U31: ="∆ "&'Lead PL'!D144 -> ∆ Dummy 2 | V31: ="∆ "&'Lead PL'!D145 -> ∆ Dummy 3 | W31: ="EBITDA FY" & RIGHT(YEAR(Cockpit!E33),2) & " Act." -> EBITDA FY23 Act. | X31: =C31 -> ∆ Revenues | Y31: =D31 -> ∆ Change in inventory | Z31: =E31 -> ∆ Own work capitalized | AA31: =F31 -> ∆ Dummy 1 | AB31: =G31 -> ∆ Dummy 2 | AC31: =H31 -> ∆ Dummy 3 | AD31: =I31 -> ∆ Cost of materials | AE31: =J31 -> ∆ Personnel expenses | ... AQ31: =V31 -> ∆ Dummy 3 | AR31: ="EBITDA FY" & RIGHT(YEAR(Cockpit!F33),2) & " Act." -> EBITDA FY24 Act.
A33: EBITDA | B33: ='Lead PL'!F146 -> 0 | C33: ='Lead PL'!G9-'Lead PL'!F9 -> 0 | D33: ='Lead PL'!G18-'Lead PL'!F18 -> 0 | E33: ='Lead PL'!G27-'Lead PL'!F27 -> 0 | F33: ='Lead PL'!G36-'Lead PL'!F36 -> 0 | G33: ='Lead PL'!G37-'Lead PL'!F37 -> 0 | H33: ='Lead PL'!G38-'Lead PL'!F38 -> 0 | I33: ='Lead PL'!G40-'Lead PL'!F40 -> 0 | J33: ='Lead PL'!G53-'Lead PL'!F53 -> 0 | K33: ='Lead PL'!G62-'Lead PL'!F62 -> 0 | L33: ='Lead PL'!G71-'Lead PL'!F71 -> 0 | M33: ='Lead PL'!G80-'Lead PL'!F80 -> 0 | N33: ='Lead PL'!G89-'Lead PL'!F89 -> 0 | O33: ='Lead PL'!G98-'Lead PL'!F98 -> 0 | P33: ='Lead PL'!G107-'Lead PL'!F107 -> 0 | Q33: ='Lead PL'!G116-'Lead PL'!F116 -> 0 | R33: ='Lead PL'!G125-'Lead PL'!F125 -> 0 | S33: ='Lead PL'!G134-'Lead PL'!F134 -> 0 | T33: ='Lead PL'!G143-'Lead PL'!F143 -> 0 | U33: ='Lead PL'!G144-'Lead PL'!F144 -> 0 | V33: ='Lead PL'!G145-'Lead PL'!F145 -> 0 | W33: =SUM(B33:V33) -> 0 | X33: ='Lead PL'!H9-'Lead PL'!G9 -> 0 | Y33: ='Lead PL'!H18-'Lead PL'!G18 -> 0 | Z33: ='Lead PL'!H27-'Lead PL'!G27 -> 0 | AA33: ='Lead PL'!H36-'Lead PL'!G36 -> 0 | AB33: ='Lead PL'!H37-'Lead PL'!G37 -> 0 | AC33: ='Lead PL'!H38-'Lead PL'!G38 -> 0 | AD33: ='Lead PL'!H40-'Lead PL'!G40 -> 0 | AE33: ='Lead PL'!H53-'Lead PL'!G53 -> 0 | AF33: ='Lead PL'!H62-'Lead PL'!G62 -> 0 | AG33: ='Lead PL'!H71-'Lead PL'!G71 -> 0 | AH33: ='Lead PL'!H80-'Lead PL'!G80 -> 0 | AI33: ='Lead PL'!H89-'Lead PL'!G89 -> 0 | AJ33: ='Lead PL'!H98-'Lead PL'!G98 -> 0 | AK33: ='Lead PL'!H107-'Lead PL'!G107 -> 0 | AL33: ='Lead PL'!H116-'Lead PL'!G116 -> 0 | AM33: ='Lead PL'!H125-'Lead PL'!G125 -> 0 | AN33: ='Lead PL'!H134-'Lead PL'!G134 -> 0 | AO33: ='Lead PL'!H143-'Lead PL'!G143 -> 0 | AP33: ='Lead PL'!H144-'Lead PL'!G144 -> 0 | AQ33: ='Lead PL'!H145-'Lead PL'!G145 -> 0 | AR33: =SUM(W33:AQ33) -> 0
A34: Check | W34: =W33-'Lead PL'!G146 -> 0 | AR34: =AR33-'Lead PL'!H146 -> 0
A64: Monthly Trade Working Capital
B67: =NA_monthly!F6 -> 44592 | C67: =NA_monthly!G6 -> 44620 | D67: =NA_monthly!H6 -> 44651 | E67: =NA_monthly!I6 -> 44681 | F67: =NA_monthly!J6 -> 44712 | G67: =NA_monthly!K6 -> 44742 | H67: =NA_monthly!L6 -> 44773 | I67: =NA_monthly!M6 -> 44804 | ... AV67: =NA_monthly!AZ6 -> 45991
A68: =NA_monthly!D16 -> Inventories | B68: =NA_monthly!F16 -> 0 | C68: =NA_monthly!G16 -> 0 | D68: =NA_monthly!H16 -> 0 | E68: =NA_monthly!I16 -> 0 | F68: =NA_monthly!J16 -> 0 | G68: =NA_monthly!K16 -> 0 | H68: =NA_monthly!L16 -> 0 | I68: =NA_monthly!M16 -> 0 | ... AV68: =NA_monthly!AZ16 -> 0
A69: =NA_monthly!D17 -> Trade receivables | B69: =NA_monthly!F17 -> 0 | C69: =NA_monthly!G17 -> 0 | D69: =NA_monthly!H17 -> 0 | E69: =NA_monthly!I17 -> 0 | F69: =NA_monthly!J17 -> 0 | G69: =NA_monthly!K17 -> 0 | H69: =NA_monthly!L17 -> 0 | I69: =NA_monthly!M17 -> 0 | ... AV69: =NA_monthly!AZ17 -> 0
A70: =NA_monthly!D18 -> Trade payables | B70: =NA_monthly!F18 -> 0 | C70: =NA_monthly!G18 -> 0 | D70: =NA_monthly!H18 -> 0 | E70: =NA_monthly!I18 -> 0 | F70: =NA_monthly!J18 -> 0 | G70: =NA_monthly!K18 -> 0 | H70: =NA_monthly!L18 -> 0 | I70: =NA_monthly!M18 -> 0 | ... AV70: =NA_monthly!AZ18 -> 0
A71: =NA_monthly!D19 -> Advance payments received | B71: =NA_monthly!F19 -> 0 | C71: =NA_monthly!G19 -> 0 | D71: =NA_monthly!H19 -> 0 | E71: =NA_monthly!I19 -> 0 | F71: =NA_monthly!J19 -> 0 | G71: =NA_monthly!K19 -> 0 | H71: =NA_monthly!L19 -> 0 | I71: =NA_monthly!M19 -> 0 | ... AV71: =NA_monthly!AZ19 -> 0
A72: =NA_monthly!D23 -> Trade working capital | B72: =NA_monthly!F23 -> 0 | C72: =NA_monthly!G23 -> 0 | D72: =NA_monthly!H23 -> 0 | E72: =NA_monthly!I23 -> 0 | F72: =NA_monthly!J23 -> 0 | G72: =NA_monthly!K23 -> 0 | H72: =NA_monthly!L23 -> 0 | I72: =NA_monthly!M23 -> 0 | ... AV72: =NA_monthly!AZ23 -> 0
A73: =NA_monthly!D43 -> Net working capital | B73: =NA_monthly!F43 -> 0 | C73: =NA_monthly!G43 -> 0 | D73: =NA_monthly!H43 -> 0 | E73: =NA_monthly!I43 -> 0 | F73: =NA_monthly!J43 -> 0 | G73: =NA_monthly!K43 -> 0 | H73: =NA_monthly!L43 -> 0 | I73: =NA_monthly!M43 -> 0 | ... AV73: =NA_monthly!AZ43 -> 0
A74: =NA_monthly!D44 -> Cash | B74: =NA_monthly!F44 -> 0 | C74: =NA_monthly!G44 -> 0 | D74: =NA_monthly!H44 -> 0 | E74: =NA_monthly!I44 -> 0 | F74: =NA_monthly!J44 -> 0 | G74: =NA_monthly!K44 -> 0 | H74: =NA_monthly!L44 -> 0 | I74: =NA_monthly!M44 -> 0 | ... AV74: =NA_monthly!AZ44 -> 0
A75: =PL_monthly!D9 -> Revenues | B75: =PL_monthly!F9 -> 0 | C75: =PL_monthly!G9 -> 0 | D75: =PL_monthly!H9 -> 0 | E75: =PL_monthly!I9 -> 0 | F75: =PL_monthly!J9 -> 0 | G75: =PL_monthly!K9 -> 0 | H75: =PL_monthly!L9 -> 0 | I75: =PL_monthly!M9 -> 0 | ... AV75: =PL_monthly!AZ9 -> 0
A76: TWC in % LTM Revenue | B76: =IF(NA_monthly!F108="n.a.",0,NA_monthly!F108) -> 0 | C76: =IF(NA_monthly!G108="n.a.",0,NA_monthly!G108) -> 0 | D76: =IF(NA_monthly!H108="n.a.",0,NA_monthly!H108) -> 0 | E76: =IF(NA_monthly!I108="n.a.",0,NA_monthly!I108) -> 0 | F76: =IF(NA_monthly!J108="n.a.",0,NA_monthly!J108) -> 0 | G76: =IF(NA_monthly!K108="n.a.",0,NA_monthly!K108) -> 0 | H76: =IF(NA_monthly!L108="n.a.",0,NA_monthly!L108) -> 0 | I76: =IF(NA_monthly!M108="n.a.",0,NA_monthly!M108) -> 0 | ... AV76: =IF(NA_monthly!AZ108="n.a.",0,NA_monthly!AZ108) -> 0
A100: Cash Conversion Cycle
B103: =NA_TWC!F6 -> 44926 | C103: =NA_TWC!G6 -> 45291 | D103: =NA_TWC!H6 -> 45657 | E103: =NA_TWC!I6 -> 45808
A105: Ø Days inventory outstanding (DIO) | B105: =NA_TWC!F70 -> n/a | C105: =NA_TWC!G70 -> n/a | D105: =NA_TWC!H70 -> n/a | E105: =NA_TWC!I70 -> n/a
A106: Ø Days sales outstanding (DSO) | B106: =NA_TWC!F71 -> n/a | C106: =NA_TWC!G71 -> n/a | D106: =NA_TWC!H71 -> n/a | E106: =NA_TWC!I71 -> n/a
A107: Ø Days payables outstanding (DPO) | B107: =NA_TWC!F72 -> n/a | C107: =NA_TWC!G72 -> n/a | D107: =NA_TWC!H72 -> n/a | E107: =NA_TWC!I72 -> n/a
A108: Cash conversion cycle | B108: =NA_TWC!F73 -> 0 | C108: =NA_TWC!G73 -> 0 | D108: =NA_TWC!H73 -> 0 | E108: =NA_TWC!I73 -> 0
A115: TOP Customer Analyse
B117: Customer 1 | C117: Customer 2 | D117: Customer 3 | E117: Customer 4 | F117: Customer 5
A119: FYXX
A120: FYXX
A121: FYXX
...

Sheet Lead >>

Sheet Trial Balance Dropdown
A1: Mapping_Dropdown_as_reported | C1: BT_adjustment_Dropdown
A2: /profit and loss | C2: /btadjustment/QOE/normalization_1
A3: /profit and loss/income | C3: /btadjustment/QOE/normalization_2
A4: /profit and loss/income/sales | C4: /btadjustment/QOE/normalization_3
A5: /profit and loss/income/increase in inventory | C5: /btadjustment/QOE/normalization_4
A6: /profit and loss/income/change in inventory | C6: /btadjustment/QOE/normalization_5
A7: /profit and loss/income/own work capitalised | C7: /btadjustment/QOE/normalization_6
A8: /profit and loss/income/income from investments | C8: /btadjustment/QOE/proforma_1
A9: /profit and loss/income/income from other securities and loans of financial assets | C9: /btadjustment/QOE/proforma_2
A10: /profit and loss/income/interest income | C10: /btadjustment/QOE/proforma_3
A11: /profit and loss/income/other income | C11: /btadjustment/QOE/proforma_4
A12: /profit and loss/expense | C12: /btadjustment/QOE/other items_1
... A49: /net debt/securities | C49: /btadjustment/net deb/other items_6
A50: /net debt/cash and cash equivalent
A51: /net debt/provisions for pensions and similar obligations
A52: /net debt/tax provisions
A53: /net debt/other provisions
A54: /net debt/bonds issued
A55: /net debt/liabilities to credit institutions
A56: /net debt/liabilities to shareholders
A57: /net debt/debt like item
A58: /fixed assets
A59: /fixed assets/intangible assets
A60: /fixed assets/intangible assets/self developed intangible assets
A61: /fixed assets/intangible assets/patents, licenses, trademarks and other
... A93: /other/deferred tax liabilities

Sheet Lead PL
C1: Technische Zeile --> nicht löschen | D1: Technische Zeile --> nicht löschen | E1: =IFERROR(E4,E6) -> 44561 | F1: =IFERROR(F4,F6) -> 44926 | G1: =IFERROR(G4,G6) -> 45291 | H1: =IFERROR(H4,H6) -> 45657 | I1: =IFERROR(I4,I6) -> 45808 | J1: =IFERROR(J4,J6) -> 45808 | K1: =IFERROR(K4,K6) -> 46022 | L1: =IFERROR(L4,L6) -> 46387 | ... N1: =IFERROR(N4,N6) -> 47118
C4: =Cockpit!$C$4 -> Template | E4: =Cockpit!C33 -> 44561 | F4: =Cockpit!D33 -> 44926 | G4: =Cockpit!E33 -> 45291 | H4: =Cockpit!F33 -> 45657 | I4: =Cockpit!G33 -> 45808 | J4: =Cockpit!H33 -> 45808 | K4: =Cockpit!I33 -> 46022 | L4: =Cockpit!J33 -> 46387 | ... N4: =Cockpit!L33 -> 47118 | P4: CAGR | Q4: CAGR
C5: ="in T"&Cockpit!$C$5 -> in TEUR | E5: =Cockpit!C34 -> IST | F5: =Cockpit!D34 -> IST | G5: =Cockpit!E34 -> IST | H5: =Cockpit!F34 -> IST | I5: =Cockpit!G34 -> LTM | J5: =Cockpit!H34 -> YTD | K5: =Cockpit!I34 -> Plan | L5: =Cockpit!J34 -> Plan | ... N5: =Cockpit!L34 -> Plan | P5: IST | Q5: =Cockpit!$C$27 -> Plan | T5: Ticker 1 (NA-Zeile / Konto) | U5: Ticker 2 (Klasse) | V5: Zeilentyp
D6: =Cockpit!$C$4 -> Template | E6: =Cockpit!C33 -> 44561 | F6: =Cockpit!D33 -> 44926 | G6: =Cockpit!E33 -> 45291 | H6: =Cockpit!F33 -> 45657 | I6: =Cockpit!G33 -> 45808 | J6: =Cockpit!H33 -> 45808 | K6: =Cockpit!I33 -> 46022 | L6: =Cockpit!J33 -> 46387 | ... N6: =Cockpit!L33 -> 47118 | P6: CAGR | Q6: CAGR
D7: ="in k"&Cockpit!$C$5 -> in kEUR | E7: =Cockpit!C34 -> IST | F7: =Cockpit!D34 -> IST | G7: =Cockpit!E34 -> IST | H7: =Cockpit!F34 -> IST | I7: =Cockpit!G34 -> LTM | J7: =Cockpit!H34 -> YTD | K7: =Cockpit!I34 -> Plan | L7: =Cockpit!J34 -> Plan | ... N7: =Cockpit!L34 -> Plan | P7: =Cockpit!$C$19 -> IST | Q7: =Cockpit!$C$27 -> Plan | T7: Classification BT
C9: Umsatzerlöse | D9: Revenues | E9: =SUMIFS(Mastersheet!$F$2:$F$400,Mastersheet!$D$2:$D$400,$T9,Mastersheet!$C$2:$C$400,$U9)/1000 -> 0 | F9: =SUMIFS(Mastersheet!$G$2:$G$400,Mastersheet!$D$2:$D$400,$T9,Mastersheet!$C$2:$C$400,$U9)/1000 -> 0 | G9: =SUMIFS(Mastersheet!$H$2:$H$400,Mastersheet!$D$2:$D$400,$T9,Mastersheet!$C$2:$C$400,$U9)/1000 -> 0 | H9: =SUMIFS(Mastersheet!$I$2:$I$400,Mastersheet!$D$2:$D$400,$T9,Mastersheet!$C$2:$C$400,$U9)/1000 -> 0 | I9: =SUMIFS(Mastersheet!$J$2:$J$400,Mastersheet!$D$2:$D$400,$T9,Mastersheet!$C$2:$C$400,$U9)/1000 -> 0 | J9: =SUMIFS(Mastersheet!$K$2:$K$400,Mastersheet!$D$2:$D$400,$T9,Mastersheet!$C$2:$C$400,$U9)/1000 -> 0 | K9: =SUMIFS(Mastersheet!$L$2:$L$400,Mastersheet!$D$2:$D$400,$T9,Mastersheet!$C$2:$C$400,$U9)/1000 -> 0 | L9: =SUMIFS(Mastersheet!$M$2:$M$400,Mastersheet!$D$2:$D$400,$T9,Mastersheet!$C$2:$C$400,$U9)/1000 -> 0 | M9: =SUMIFS(Mastersheet!$N$2:$N$400,Mastersheet!$D$2:$D$400,$T9,Mastersheet!$C$2:$C$400,$U9)/1000 -> 0 | N9: =SUMIFS(Mastersheet!$O$2:$O$400,Mastersheet!$D$2:$D$400,$T9,Mastersheet!$C$2:$C$400,$U9)/1000 -> 0 | P9: =IFERROR(((H9/F9)^(1/(($H$1-$F$1)/365)))-1,"n/a") -> n/a | Q9: =IFERROR(((N9/H9)^(1/(($N$1-$H$1)/365)))-1,"n/a") -> n/a | T9: Umsatzerloese | U9: PL | V9: POS
E10: =IF($T$10="","",SUMIFS(Mastersheet!$F$2:$F$400,Mastersheet!$A$2:$A$400,$T$10)/1000) | F10: =IF($T$10="","",SUMIFS(Mastersheet!$G$2:$G$400,Mastersheet!$A$2:$A$400,$T$10)/1000) | G10: =IF($T$10="","",SUMIFS(Mastersheet!$H$2:$H$400,Mastersheet!$A$2:$A$400,$T$10)/1000) | H10: =IF($T$10="","",SUMIFS(Mastersheet!$I$2:$I$400,Mastersheet!$A$2:$A$400,$T$10)/1000) | I10: =IF($T$10="","",SUMIFS(Mastersheet!$J$2:$J$400,Mastersheet!$A$2:$A$400,$T$10)/1000) | J10: =IF($T$10="","",SUMIFS(Mastersheet!$K$2:$K$400,Mastersheet!$A$2:$A$400,$T$10)/1000) | K10: =IF($T$10="","",SUMIFS(Mastersheet!$L$2:$L$400,Mastersheet!$A$2:$A$400,$T$10)/1000) | L10: =IF($T$10="","",SUMIFS(Mastersheet!$M$2:$M$400,Mastersheet!$A$2:$A$400,$T$10)/1000) | M10: =IF($T$10="","",SUMIFS(Mastersheet!$N$2:$N$400,Mastersheet!$A$2:$A$400,$T$10)/1000) | N10: =IF($T$10="","",SUMIFS(Mastersheet!$O$2:$O$400,Mastersheet!$A$2:$A$400,$T$10)/1000) | U10: Account | V10: KTO
E11: =IF($T$11="","",SUMIFS(Mastersheet!$F$2:$F$400,Mastersheet!$A$2:$A$400,$T$11)/1000) | F11: =IF($T$11="","",SUMIFS(Mastersheet!$G$2:$G$400,Mastersheet!$A$2:$A$400,$T$11)/1000) | G11: =IF($T$11="","",SUMIFS(Mastersheet!$H$2:$H$400,Mastersheet!$A$2:$A$400,$T$11)/1000) | H11: =IF($T$11="","",SUMIFS(Mastersheet!$I$2:$I$400,Mastersheet!$A$2:$A$400,$T$11)/1000) | I11: =IF($T$11="","",SUMIFS(Mastersheet!$J$2:$J$400,Mastersheet!$A$2:$A$400,$T$11)/1000) | J11: =IF($T$11="","",SUMIFS(Mastersheet!$K$2:$K$400,Mastersheet!$A$2:$A$400,$T$11)/1000) | K11: =IF($T$11="","",SUMIFS(Mastersheet!$L$2:$L$400,Mastersheet!$A$2:$A$400,$T$11)/1000) | L11: =IF($T$11="","",SUMIFS(Mastersheet!$M$2:$M$400,Mastersheet!$A$2:$A$400,$T$11)/1000) | M11: =IF($T$11="","",SUMIFS(Mastersheet!$N$2:$N$400,Mastersheet!$A$2:$A$400,$T$11)/1000) | N11: =IF($T$11="","",SUMIFS(Mastersheet!$O$2:$O$400,Mastersheet!$A$2:$A$400,$T$11)/1000) | U11: Account | V11: KTO
E12: =IF($T$12="","",SUMIFS(Mastersheet!$F$2:$F$400,Mastersheet!$A$2:$A$400,$T$12)/1000) | F12: =IF($T$12="","",SUMIFS(Mastersheet!$G$2:$G$400,Mastersheet!$A$2:$A$400,$T$12)/1000) | G12: =IF($T$12="","",SUMIFS(Mastersheet!$H$2:$H$400,Mastersheet!$A$2:$A$400,$T$12)/1000) | H12: =IF($T$12="","",SUMIFS(Mastersheet!$I$2:$I$400,Mastersheet!$A$2:$A$400,$T$12)/1000) | I12: =IF($T$12="","",SUMIFS(Mastersheet!$J$2:$J$400,Mastersheet!$A$2:$A$400,$T$12)/1000) | J12: =IF($T$12="","",SUMIFS(Mastersheet!$K$2:$K$400,Mastersheet!$A$2:$A$400,$T$12)/1000) | K12: =IF($T$12="","",SUMIFS(Mastersheet!$L$2:$L$400,Mastersheet!$A$2:$A$400,$T$12)/1000) | L12: =IF($T$12="","",SUMIFS(Mastersheet!$M$2:$M$400,Mastersheet!$A$2:$A$400,$T$12)/1000) | M12: =IF($T$12="","",SUMIFS(Mastersheet!$N$2:$N$400,Mastersheet!$A$2:$A$400,$T$12)/1000) | N12: =IF($T$12="","",SUMIFS(Mastersheet!$O$2:$O$400,Mastersheet!$A$2:$A$400,$T$12)/1000) | U12: Account | V12: KTO
E13: =IF($T$13="","",SUMIFS(Mastersheet!$F$2:$F$400,Mastersheet!$A$2:$A$400,$T$13)/1000) | F13: =IF($T$13="","",SUMIFS(Mastersheet!$G$2:$G$400,Mastersheet!$A$2:$A$400,$T$13)/1000) | G13: =IF($T$13="","",SUMIFS(Mastersheet!$H$2:$H$400,Mastersheet!$A$2:$A$400,$T$13)/1000) | H13: =IF($T$13="","",SUMIFS(Mastersheet!$I$2:$I$400,Mastersheet!$A$2:$A$400,$T$13)/1000) | I13: =IF($T$13="","",SUMIFS(Mastersheet!$J$2:$J$400,Mastersheet!$A$2:$A$400,$T$13)/1000) | J13: =IF($T$13="","",SUMIFS(Mastersheet!$K$2:$K$400,Mastersheet!$A$2:$A$400,$T$13)/1000) | K13: =IF($T$13="","",SUMIFS(Mastersheet!$L$2:$L$400,Mastersheet!$A$2:$A$400,$T$13)/1000) | L13: =IF($T$13="","",SUMIFS(Mastersheet!$M$2:$M$400,Mastersheet!$A$2:$A$400,$T$13)/1000) | M13: =IF($T$13="","",SUMIFS(Mastersheet!$N$2:$N$400,Mastersheet!$A$2:$A$400,$T$13)/1000) | N13: =IF($T$13="","",SUMIFS(Mastersheet!$O$2:$O$400,Mastersheet!$A$2:$A$400,$T$13)/1000) | U13: Account | V13: KTO
E14: =IF($T$14="","",SUMIFS(Mastersheet!$F$2:$F$400,Mastersheet!$A$2:$A$400,$T$14)/1000) | F14: =IF($T$14="","",SUMIFS(Mastersheet!$G$2:$G$400,Mastersheet!$A$2:$A$400,$T$14)/1000) | G14: =IF($T$14="","",SUMIFS(Mastersheet!$H$2:$H$400,Mastersheet!$A$2:$A$400,$T$14)/1000) | H14: =IF($T$14="","",SUMIFS(Mastersheet!$I$2:$I$400,Mastersheet!$A$2:$A$400,$T$14)/1000) | I14: =IF($T$14="","",SUMIFS(Mastersheet!$J$2:$J$400,Mastersheet!$A$2:$A$400,$T$14)/1000) | J14: =IF($T$14="","",SUMIFS(Mastersheet!$K$2:$K$400,Mastersheet!$A$2:$A$400,$T$14)/1000) | K14: =IF($T$14="","",SUMIFS(Mastersheet!$L$2:$L$400,Mastersheet!$A$2:$A$400,$T$14)/1000) | L14: =IF($T$14="","",SUMIFS(Mastersheet!$M$2:$M$400,Mastersheet!$A$2:$A$400,$T$14)/1000) | M14: =IF($T$14="","",SUMIFS(Mastersheet!$N$2:$N$400,Mastersheet!$A$2:$A$400,$T$14)/1000) | N14: =IF($T$14="","",SUMIFS(Mastersheet!$O$2:$O$400,Mastersheet!$A$2:$A$400,$T$14)/1000) | U14: Account | V14: KTO
E15: =IF($T$15="","",SUMIFS(Mastersheet!$F$2:$F$400,Mastersheet!$A$2:$A$400,$T$15)/1000) | F15: =IF($T$15="","",SUMIFS(Mastersheet!$G$2:$G$400,Mastersheet!$A$2:$A$400,$T$15)/1000) | G15: =IF($T$15="","",SUMIFS(Mastersheet!$H$2:$H$400,Mastersheet!$A$2:$A$400,$T$15)/1000) | H15: =IF($T$15="","",SUMIFS(Mastersheet!$I$2:$I$400,Mastersheet!$A$2:$A$400,$T$15)/1000) | I15: =IF($T$15="","",SUMIFS(Mastersheet!$J$2:$J$400,Mastersheet!$A$2:$A$400,$T$15)/1000) | J15: =IF($T$15="","",SUMIFS(Mastersheet!$K$2:$K$400,Mastersheet!$A$2:$A$400,$T$15)/1000) | K15: =IF($T$15="","",SUMIFS(Mastersheet!$L$2:$L$400,Mastersheet!$A$2:$A$400,$T$15)/1000) | L15: =IF($T$15="","",SUMIFS(Mastersheet!$M$2:$M$400,Mastersheet!$A$2:$A$400,$T$15)/1000) | M15: =IF($T$15="","",SUMIFS(Mastersheet!$N$2:$N$400,Mastersheet!$A$2:$A$400,$T$15)/1000) | N15: =IF($T$15="","",SUMIFS(Mastersheet!$O$2:$O$400,Mastersheet!$A$2:$A$400,$T$15)/1000) | U15: Account | V15: KTO
E16: =IF($T$16="","",SUMIFS(Mastersheet!$F$2:$F$400,Mastersheet!$A$2:$A$400,$T$16)/1000) | F16: =IF($T$16="","",SUMIFS(Mastersheet!$G$2:$G$400,Mastersheet!$A$2:$A$400,$T$16)/1000) | G16: =IF($T$16="","",SUMIFS(Mastersheet!$H$2:$H$400,Mastersheet!$A$2:$A$400,$T$16)/1000) | H16: =IF($T$16="","",SUMIFS(Mastersheet!$I$2:$I$400,Mastersheet!$A$2:$A$400,$T$16)/1000) | I16: =IF($T$16="","",SUMIFS(Mastersheet!$J$2:$J$400,Mastersheet!$A$2:$A$400,$T$16)/1000) | J16: =IF($T$16="","",SUMIFS(Mastersheet!$K$2:$K$400,Mastersheet!$A$2:$A$400,$T$16)/1000) | K16: =IF($T$16="","",SUMIFS(Mastersheet!$L$2:$L$400,Mastersheet!$A$2:$A$400,$T$16)/1000) | L16: =IF($T$16="","",SUMIFS(Mastersheet!$M$2:$M$400,Mastersheet!$A$2:$A$400,$T$16)/1000) | M16: =IF($T$16="","",SUMIFS(Mastersheet!$N$2:$N$400,Mastersheet!$A$2:$A$400,$T$16)/1000) | N16: =IF($T$16="","",SUMIFS(Mastersheet!$O$2:$O$400,Mastersheet!$A$2:$A$400,$T$16)/1000) | U16: Account | V16: KTO
E17: =IF($T$17="","",SUMIFS(Mastersheet!$F$2:$F$400,Mastersheet!$A$2:$A$400,$T$17)/1000) | F17: =IF($T$17="","",SUMIFS(Mastersheet!$G$2:$G$400,Mastersheet!$A$2:$A$400,$T$17)/1000) | G17: =IF($T$17="","",SUMIFS(Mastersheet!$H$2:$H$400,Mastersheet!$A$2:$A$400,$T$17)/1000) | H17: =IF($T$17="","",SUMIFS(Mastersheet!$I$2:$I$400,Mastersheet!$A$2:$A$400,$T$17)/1000) | I17: =IF($T$17="","",SUMIFS(Mastersheet!$J$2:$J$400,Mastersheet!$A$2:$A$400,$T$17)/1000) | J17: =IF($T$17="","",SUMIFS(Mastersheet!$K$2:$K$400,Mastersheet!$A$2:$A$400,$T$17)/1000) | K17: =IF($T$17="","",SUMIFS(Mastersheet!$L$2:$L$400,Mastersheet!$A$2:$A$400,$T$17)/1000) | L17: =IF($T$17="","",SUMIFS(Mastersheet!$M$2:$M$400,Mastersheet!$A$2:$A$400,$T$17)/1000) | M17: =IF($T$17="","",SUMIFS(Mastersheet!$N$2:$N$400,Mastersheet!$A$2:$A$400,$T$17)/1000) | N17: =IF($T$17="","",SUMIFS(Mastersheet!$O$2:$O$400,Mastersheet!$A$2:$A$400,$T$17)/1000) | U17: Account | V17: KTO
C18: Bestandsveränderung | D18: Change in inventory | E18: =SUMIFS(Mastersheet!$F$2:$F$400,Mastersheet!$D$2:$D$400,$T18,Mastersheet!$C$2:$C$400,$U18)/1000 -> 0 | F18: =SUMIFS(Mastersheet!$G$2:$G$400,Mastersheet!$D$2:$D$400,$T18,Mastersheet!$C$2:$C$400,$U18)/1000 -> 0 | G18: =SUMIFS(Mastersheet!$H$2:$H$400,Mastersheet!$D$2:$D$400,$T18,Mastersheet!$C$2:$C$400,$U18)/1000 -> 0 | H18: =SUMIFS(Mastersheet!$I$2:$I$400,Mastersheet!$D$2:$D$400,$T18,Mastersheet!$C$2:$C$400,$U18)/1000 -> 0 | I18: =SUMIFS(Mastersheet!$J$2:$J$400,Mastersheet!$D$2:$D$400,$T18,Mastersheet!$C$2:$C$400,$U18)/1000 -> 0 | J18: =SUMIFS(Mastersheet!$K$2:$K$400,Mastersheet!$D$2:$D$400,$T18,Mastersheet!$C$2:$C$400,$U18)/1000 -> 0 | K18: =SUMIFS(Mastersheet!$L$2:$L$400,Mastersheet!$D$2:$D$400,$T18,Mastersheet!$C$2:$C$400,$U18)/1000 -> 0 | L18: =SUMIFS(Mastersheet!$M$2:$M$400,Mastersheet!$D$2:$D$400,$T18,Mastersheet!$C$2:$C$400,$U18)/1000 -> 0 | M18: =SUMIFS(Mastersheet!$N$2:$N$400,Mastersheet!$D$2:$D$400,$T18,Mastersheet!$C$2:$C$400,$U18)/1000 -> 0 | N18: =SUMIFS(Mastersheet!$O$2:$O$400,Mastersheet!$D$2:$D$400,$T18,Mastersheet!$C$2:$C$400,$U18)/1000 -> 0 | P18: =IFERROR(((H18/F18)^(1/(($H$1-$F$1)/365)))-1,"n/a") -> n/a | Q18: =IFERROR(((N18/H18)^(1/(($N$1-$H$1)/365)))-1,"n/a") -> n/a | T18: Bestandsveraenderung | U18: PL | V18: POS
E19: =IF($T$19="","",SUMIFS(Mastersheet!$F$2:$F$400,Mastersheet!$A$2:$A$400,$T$19)/1000) | F19: =IF($T$19="","",SUMIFS(Mastersheet!$G$2:$G$400,Mastersheet!$A$2:$A$400,$T$19)/1000) | G19: =IF($T$19="","",SUMIFS(Mastersheet!$H$2:$H$400,Mastersheet!$A$2:$A$400,$T$19)/1000) | H19: =IF($T$19="","",SUMIFS(Mastersheet!$I$2:$I$400,Mastersheet!$A$2:$A$400,$T$19)/1000) | I19: =IF($T$19="","",SUMIFS(Mastersheet!$J$2:$J$400,Mastersheet!$A$2:$A$400,$T$19)/1000) | J19: =IF($T$19="","",SUMIFS(Mastersheet!$K$2:$K$400,Mastersheet!$A$2:$A$400,$T$19)/1000) | K19: =IF($T$19="","",SUMIFS(Mastersheet!$L$2:$L$400,Mastersheet!$A$2:$A$400,$T$19)/1000) | L19: =IF($T$19="","",SUMIFS(Mastersheet!$M$2:$M$400,Mastersheet!$A$2:$A$400,$T$19)/1000) | M19: =IF($T$19="","",SUMIFS(Mastersheet!$N$2:$N$400,Mastersheet!$A$2:$A$400,$T$19)/1000) | N19: =IF($T$19="","",SUMIFS(Mastersheet!$O$2:$O$400,Mastersheet!$A$2:$A$400,$T$19)/1000) | U19: Account | V19: KTO
E20: =IF($T$20="","",SUMIFS(Mastersheet!$F$2:$F$400,Mastersheet!$A$2:$A$400,$T$20)/1000) | F20: =IF($T$20="","",SUMIFS(Mastersheet!$G$2:$G$400,Mastersheet!$A$2:$A$400,$T$20)/1000) | G20: =IF($T$20="","",SUMIFS(Mastersheet!$H$2:$H$400,Mastersheet!$A$2:$A$400,$T$20)/1000) | H20: =IF($T$20="","",SUMIFS(Mastersheet!$I$2:$I$400,Mastersheet!$A$2:$A$400,$T$20)/1000) | I20: =IF($T$20="","",SUMIFS(Mastersheet!$J$2:$J$400,Mastersheet!$A$2:$A$400,$T$20)/1000) | J20: =IF($T$20="","",SUMIFS(Mastersheet!$K$2:$K$400,Mastersheet!$A$2:$A$400,$T$20)/1000) | K20: =IF($T$20="","",SUMIFS(Mastersheet!$L$2:$L$400,Mastersheet!$A$2:$A$400,$T$20)/1000) | L20: =IF($T$20="","",SUMIFS(Mastersheet!$M$2:$M$400,Mastersheet!$A$2:$A$400,$T$20)/1000) | M20: =IF($T$20="","",SUMIFS(Mastersheet!$N$2:$N$400,Mastersheet!$A$2:$A$400,$T$20)/1000) | N20: =IF($T$20="","",SUMIFS(Mastersheet!$O$2:$O$400,Mastersheet!$A$2:$A$400,$T$20)/1000) | U20: Account | V20: KTO
E21: =IF($T$21="","",SUMIFS(Mastersheet!$F$2:$F$400,Mastersheet!$A$2:$A$400,$T$21)/1000) | F21: =IF($T$21="","",SUMIFS(Mastersheet!$G$2:$G$400,Mastersheet!$A$2:$A$400,$T$21)/1000) | G21: =IF($T$21="","",SUMIFS(Mastersheet!$H$2:$H$400,Mastersheet!$A$2:$A$400,$T$21)/1000) | H21: =IF($T$21="","",SUMIFS(Mastersheet!$I$2:$I$400,Mastersheet!$A$2:$A$400,$T$21)/1000) | I21: =IF($T$21="","",SUMIFS(Mastersheet!$J$2:$J$400,Mastersheet!$A$2:$A$400,$T$21)/1000) | J21: =IF($T$21="","",SUMIFS(Mastersheet!$K$2:$K$400,Mastersheet!$A$2:$A$400,$T$21)/1000) | K21: =IF($T$21="","",SUMIFS(Mastersheet!$L$2:$L$400,Mastersheet!$A$2:$A$400,$T$21)/1000) | L21: =IF($T$21="","",SUMIFS(Mastersheet!$M$2:$M$400,Mastersheet!$A$2:$A$400,$T$21)/1000) | M21: =IF($T$21="","",SUMIFS(Mastersheet!$N$2:$N$400,Mastersheet!$A$2:$A$400,$T$21)/1000) | N21: =IF($T$21="","",SUMIFS(Mastersheet!$O$2:$O$400,Mastersheet!$A$2:$A$400,$T$21)/1000) | U21: Account | V21: KTO
E22: =IF($T$22="","",SUMIFS(Mastersheet!$F$2:$F$400,Mastersheet!$A$2:$A$400,$T$22)/1000) | F22: =IF($T$22="","",SUMIFS(Mastersheet!$G$2:$G$400,Mastersheet!$A$2:$A$400,$T$22)/1000) | G22: =IF($T$22="","",SUMIFS(Mastersheet!$H$2:$H$400,Mastersheet!$A$2:$A$400,$T$22)/1000) | H22: =IF($T$22="","",SUMIFS(Mastersheet!$I$2:$I$400,Mastersheet!$A$2:$A$400,$T$22)/1000) | I22: =IF($T$22="","",SUMIFS(Mastersheet!$J$2:$J$400,Mastersheet!$A$2:$A$400,$T$22)/1000) | J22: =IF($T$22="","",SUMIFS(Mastersheet!$K$2:$K$400,Mastersheet!$A$2:$A$400,$T$22)/1000) | K22: =IF($T$22="","",SUMIFS(Mastersheet!$L$2:$L$400,Mastersheet!$A$2:$A$400,$T$22)/1000) | L22: =IF($T$22="","",SUMIFS(Mastersheet!$M$2:$M$400,Mastersheet!$A$2:$A$400,$T$22)/1000) | M22: =IF($T$22="","",SUMIFS(Mastersheet!$N$2:$N$400,Mastersheet!$A$2:$A$400,$T$22)/1000) | N22: =IF($T$22="","",SUMIFS(Mastersheet!$O$2:$O$400,Mastersheet!$A$2:$A$400,$T$22)/1000) | U22: Account | V22: KTO
E23: =IF($T$23="","",SUMIFS(Mastersheet!$F$2:$F$400,Mastersheet!$A$2:$A$400,$T$23)/1000) | F23: =IF($T$23="","",SUMIFS(Mastersheet!$G$2:$G$400,Mastersheet!$A$2:$A$400,$T$23)/1000) | G23: =IF($T$23="","",SUMIFS(Mastersheet!$H$2:$H$400,Mastersheet!$A$2:$A$400,$T$23)/1000) | H23: =IF($T$23="","",SUMIFS(Mastersheet!$I$2:$I$400,Mastersheet!$A$2:$A$400,$T$23)/1000) | I23: =IF($T$23="","",SUMIFS(Mastersheet!$J$2:$J$400,Mastersheet!$A$2:$A$400,$T$23)/1000) | J23: =IF($T$23="","",SUMIFS(Mastersheet!$K$2:$K$400,Mastersheet!$A$2:$A$400,$T$23)/1000) | K23: =IF($T$23="","",SUMIFS(Mastersheet!$L$2:$L$400,Mastersheet!$A$2:$A$400,$T$23)/1000) | L23: =IF($T$23="","",SUMIFS(Mastersheet!$M$2:$M$400,Mastersheet!$A$2:$A$400,$T$23)/1000) | M23: =IF($T$23="","",SUMIFS(Mastersheet!$N$2:$N$400,Mastersheet!$A$2:$A$400,$T$23)/1000) | N23: =IF($T$23="","",SUMIFS(Mastersheet!$O$2:$O$400,Mastersheet!$A$2:$A$400,$T$23)/1000) | U23: Account | V23: KTO
E24: =IF($T$24="","",SUMIFS(Mastersheet!$F$2:$F$400,Mastersheet!$A$2:$A$400,$T$24)/1000) | F24: =IF($T$24="","",SUMIFS(Mastersheet!$G$2:$G$400,Mastersheet!$A$2:$A$400,$T$24)/1000) | G24: =IF($T$24="","",SUMIFS(Mastersheet!$H$2:$H$400,Mastersheet!$A$2:$A$400,$T$24)/1000) | H24: =IF($T$24="","",SUMIFS(Mastersheet!$I$2:$I$400,Mastersheet!$A$2:$A$400,$T$24)/1000) | I24: =IF($T$24="","",SUMIFS(Mastersheet!$J$2:$J$400,Mastersheet!$A$2:$A$400,$T$24)/1000) | J24: =IF($T$24="","",SUMIFS(Mastersheet!$K$2:$K$400,Mastersheet!$A$2:$A$400,$T$24)/1000) | K24: =IF($T$24="","",SUMIFS(Mastersheet!$L$2:$L$400,Mastersheet!$A$2:$A$400,$T$24)/1000) | L24: =IF($T$24="","",SUMIFS(Mastersheet!$M$2:$M$400,Mastersheet!$A$2:$A$400,$T$24)/1000) | M24: =IF($T$24="","",SUMIFS(Mastersheet!$N$2:$N$400,Mastersheet!$A$2:$A$400,$T$24)/1000) | N24: =IF($T$24="","",SUMIFS(Mastersheet!$O$2:$O$400,Mastersheet!$A$2:$A$400,$T$24)/1000) | U24: Account | V24: KTO
E25: =IF($T$25="","",SUMIFS(Mastersheet!$F$2:$F$400,Mastersheet!$A$2:$A$400,$T$25)/1000) | F25: =IF($T$25="","",SUMIFS(Mastersheet!$G$2:$G$400,Mastersheet!$A$2:$A$400,$T$25)/1000) | G25: =IF($T$25="","",SUMIFS(Mastersheet!$H$2:$H$400,Mastersheet!$A$2:$A$400,$T$25)/1000) | H25: =IF($T$25="","",SUMIFS(Mastersheet!$I$2:$I$400,Mastersheet!$A$2:$A$400,$T$25)/1000) | I25: =IF($T$25="","",SUMIFS(Mastersheet!$J$2:$J$400,Mastersheet!$A$2:$A$400,$T$25)/1000) | J25: =IF($T$25="","",SUMIFS(Mastersheet!$K$2:$K$400,Mastersheet!$A$2:$A$400,$T$25)/1000) | K25: =IF($T$25="","",SUMIFS(Mastersheet!$L$2:$L$400,Mastersheet!$A$2:$A$400,$T$25)/1000) | L25: =IF($T$25="","",SUMIFS(Mastersheet!$M$2:$M$400,Mastersheet!$A$2:$A$400,$T$25)/1000) | M25: =IF($T$25="","",SUMIFS(Mastersheet!$N$2:$N$400,Mastersheet!$A$2:$A$400,$T$25)/1000) | N25: =IF($T$25="","",SUMIFS(Mastersheet!$O$2:$O$400,Mastersheet!$A$2:$A$400,$T$25)/1000) | U25: Account | V25: KTO
E26: =IF($T$26="","",SUMIFS(Mastersheet!$F$2:$F$400,Mastersheet!$A$2:$A$400,$T$26)/1000) | F26: =IF($T$26="","",SUMIFS(Mastersheet!$G$2:$G$400,Mastersheet!$A$2:$A$400,$T$26)/1000) | G26: =IF($T$26="","",SUMIFS(Mastersheet!$H$2:$H$400,Mastersheet!$A$2:$A$400,$T$26)/1000) | H26: =IF($T$26="","",SUMIFS(Mastersheet!$I$2:$I$400,Mastersheet!$A$2:$A$400,$T$26)/1000) | I26: =IF($T$26="","",SUMIFS(Mastersheet!$J$2:$J$400,Mastersheet!$A$2:$A$400,$T$26)/1000) | J26: =IF($T$26="","",SUMIFS(Mastersheet!$K$2:$K$400,Mastersheet!$A$2:$A$400,$T$26)/1000) | K26: =IF($T$26="","",SUMIFS(Mastersheet!$L$2:$L$400,Mastersheet!$A$2:$A$400,$T$26)/1000) | L26: =IF($T$26="","",SUMIFS(Mastersheet!$M$2:$M$400,Mastersheet!$A$2:$A$400,$T$26)/1000) | M26: =IF($T$26="","",SUMIFS(Mastersheet!$N$2:$N$400,Mastersheet!$A$2:$A$400,$T$26)/1000) | N26: =IF($T$26="","",SUMIFS(Mastersheet!$O$2:$O$400,Mastersheet!$A$2:$A$400,$T$26)/1000) | U26: Account | V26: KTO
C27: Aktivierte Eigenleistungen | D27: Own work capitalized | E27: =SUMIFS(Mastersheet!$F$2:$F$400,Mastersheet!$D$2:$D$400,$T27,Mastersheet!$C$2:$C$400,$U27)/1000 -> 0 | F27: =SUMIFS(Mastersheet!$G$2:$G$400,Mastersheet!$D$2:$D$400,$T27,Mastersheet!$C$2:$C$400,$U27)/1000 -> 0 | G27: =SUMIFS(Mastersheet!$H$2:$H$400,Mastersheet!$D$2:$D$400,$T27,Mastersheet!$C$2:$C$400,$U27)/1000 -> 0 | H27: =SUMIFS(Mastersheet!$I$2:$I$400,Mastersheet!$D$2:$D$400,$T27,Mastersheet!$C$2:$C$400,$U27)/1000 -> 0 | I27: =SUMIFS(Mastersheet!$J$2:$J$400,Mastersheet!$D$2:$D$400,$T27,Mastersheet!$C$2:$C$400,$U27)/1000 -> 0 | J27: =SUMIFS(Mastersheet!$K$2:$K$400,Mastersheet!$D$2:$D$400,$T27,Mastersheet!$C$2:$C$400,$U27)/1000 -> 0 | K27: =SUMIFS(Mastersheet!$L$2:$L$400,Mastersheet!$D$2:$D$400,$T27,Mastersheet!$C$2:$C$400,$U27)/1000 -> 0 | L27: =SUMIFS(Mastersheet!$M$2:$M$400,Mastersheet!$D$2:$D$400,$T27,Mastersheet!$C$2:$C$400,$U27)/1000 -> 0 | M27: =SUMIFS(Mastersheet!$N$2:$N$400,Mastersheet!$D$2:$D$400,$T27,Mastersheet!$C$2:$C$400,$U27)/1000 -> 0 | N27: =SUMIFS(Mastersheet!$O$2:$O$400,Mastersheet!$D$2:$D$400,$T27,Mastersheet!$C$2:$C$400,$U27)/1000 -> 0 | P27: =IFERROR(((H27/F27)^(1/(($H$1-$F$1)/365)))-1,"n/a") -> n/a | Q27: =IFERROR(((N27/H27)^(1/(($N$1-$H$1)/365)))-1,"n/a") -> n/a | T27: Aktivierte Eigenleistungen | U27: PL | V27: POS
E28: =IF($T$28="","",SUMIFS(Mastersheet!$F$2:$F$400,Mastersheet!$A$2:$A$400,$T$28)/1000) | F28: =IF($T$28="","",SUMIFS(Mastersheet!$G$2:$G$400,Mastersheet!$A$2:$A$400,$T$28)/1000) | G28: =IF($T$28="","",SUMIFS(Mastersheet!$H$2:$H$400,Mastersheet!$A$2:$A$400,$T$28)/1000) | H28: =IF($T$28="","",SUMIFS(Mastersheet!$I$2:$I$400,Mastersheet!$A$2:$A$400,$T$28)/1000) | I28: =IF($T$28="","",SUMIFS(Mastersheet!$J$2:$J$400,Mastersheet!$A$2:$A$400,$T$28)/1000) | J28: =IF($T$28="","",SUMIFS(Mastersheet!$K$2:$K$400,Mastersheet!$A$2:$A$400,$T$28)/1000) | K28: =IF($T$28="","",SUMIFS(Mastersheet!$L$2:$L$400,Mastersheet!$A$2:$A$400,$T$28)/1000) | L28: =IF($T$28="","",SUMIFS(Mastersheet!$M$2:$M$400,Mastersheet!$A$2:$A$400,$T$28)/1000) | M28: =IF($T$28="","",SUMIFS(Mastersheet!$N$2:$N$400,Mastersheet!$A$2:$A$400,$T$28)/1000) | N28: =IF($T$28="","",SUMIFS(Mastersheet!$O$2:$O$400,Mastersheet!$A$2:$A$400,$T$28)/1000) | U28: Account | V28: KTO
E29: =IF($T$29="","",SUMIFS(Mastersheet!$F$2:$F$400,Mastersheet!$A$2:$A$400,$T$29)/1000) | F29: =IF($T$29="","",SUMIFS(Mastersheet!$G$2:$G$400,Mastersheet!$A$2:$A$400,$T$29)/1000) | G29: =IF($T$29="","",SUMIFS(Mastersheet!$H$2:$H$400,Mastersheet!$A$2:$A$400,$T$29)/1000) | H29: =IF($T$29="","",SUMIFS(Mastersheet!$I$2:$I$400,Mastersheet!$A$2:$A$400,$T$29)/1000) | I29: =IF($T$29="","",SUMIFS(Mastersheet!$J$2:$J$400,Mastersheet!$A$2:$A$400,$T$29)/1000) | J29: =IF($T$29="","",SUMIFS(Mastersheet!$K$2:$K$400,Mastersheet!$A$2:$A$400,$T$29)/1000) | K29: =IF($T$29="","",SUMIFS(Mastersheet!$L$2:$L$400,Mastersheet!$A$2:$A$400,$T$29)/1000) | L29: =IF($T$29="","",SUMIFS(Mastersheet!$M$2:$M$400,Mastersheet!$A$2:$A$400,$T$29)/1000) | M29: =IF($T$29="","",SUMIFS(Mastersheet!$N$2:$N$400,Mastersheet!$A$2:$A$400,$T$29)/1000) | N29: =IF($T$29="","",SUMIFS(Mastersheet!$O$2:$O$400,Mastersheet!$A$2:$A$400,$T$29)/1000) | U29: Account | V29: KTO
E30: =IF($T$30="","",SUMIFS(Mastersheet!$F$2:$F$400,Mastersheet!$A$2:$A$400,$T$30)/1000) | F30: =IF($T$30="","",SUMIFS(Mastersheet!$G$2:$G$400,Mastersheet!$A$2:$A$400,$T$30)/1000) | G30: =IF($T$30="","",SUMIFS(Mastersheet!$H$2:$H$400,Mastersheet!$A$2:$A$400,$T$30)/1000) | H30: =IF($T$30="","",SUMIFS(Mastersheet!$I$2:$I$400,Mastersheet!$A$2:$A$400,$T$30)/1000) | I30: =IF($T$30="","",SUMIFS(Mastersheet!$J$2:$J$400,Mastersheet!$A$2:$A$400,$T$30)/1000) | J30: =IF($T$30="","",SUMIFS(Mastersheet!$K$2:$K$400,Mastersheet!$A$2:$A$400,$T$30)/1000) | K30: =IF($T$30="","",SUMIFS(Mastersheet!$L$2:$L$400,Mastersheet!$A$2:$A$400,$T$30)/1000) | L30: =IF($T$30="","",SUMIFS(Mastersheet!$M$2:$M$400,Mastersheet!$A$2:$A$400,$T$30)/1000) | M30: =IF($T$30="","",SUMIFS(Mastersheet!$N$2:$N$400,Mastersheet!$A$2:$A$400,$T$30)/1000) | N30: =IF($T$30="","",SUMIFS(Mastersheet!$O$2:$O$400,Mastersheet!$A$2:$A$400,$T$30)/1000) | U30: Account | V30: KTO
E31: =IF($T$31="","",SUMIFS(Mastersheet!$F$2:$F$400,Mastersheet!$A$2:$A$400,$T$31)/1000) | F31: =IF($T$31="","",SUMIFS(Mastersheet!$G$2:$G$400,Mastersheet!$A$2:$A$400,$T$31)/1000) | G31: =IF($T$31="","",SUMIFS(Mastersheet!$H$2:$H$400,Mastersheet!$A$2:$A$400,$T$31)/1000) | H31: =IF($T$31="","",SUMIFS(Mastersheet!$I$2:$I$400,Mastersheet!$A$2:$A$400,$T$31)/1000) | I31: =IF($T$31="","",SUMIFS(Mastersheet!$J$2:$J$400,Mastersheet!$A$2:$A$400,$T$31)/1000) | J31: =IF($T$31="","",SUMIFS(Mastersheet!$K$2:$K$400,Mastersheet!$A$2:$A$400,$T$31)/1000) | K31: =IF($T$31="","",SUMIFS(Mastersheet!$L$2:$L$400,Mastersheet!$A$2:$A$400,$T$31)/1000) | L31: =IF($T$31="","",SUMIFS(Mastersheet!$M$2:$M$400,Mastersheet!$A$2:$A$400,$T$31)/1000) | M31: =IF($T$31="","",SUMIFS(Mastersheet!$N$2:$N$400,Mastersheet!$A$2:$A$400,$T$31)/1000) | N31: =IF($T$31="","",SUMIFS(Mastersheet!$O$2:$O$400,Mastersheet!$A$2:$A$400,$T$31)/1000) | U31: Account | V31: KTO
E32: =IF($T$32="","",SUMIFS(Mastersheet!$F$2:$F$400,Mastersheet!$A$2:$A$400,$T$32)/1000) | F32: =IF($T$32="","",SUMIFS(Mastersheet!$G$2:$G$400,Mastersheet!$A$2:$A$400,$T$32)/1000) | G32: =IF($T$32="","",SUMIFS(Mastersheet!$H$2:$H$400,Mastersheet!$A$2:$A$400,$T$32)/1000) | H32: =IF($T$32="","",SUMIFS(Mastersheet!$I$2:$I$400,Mastersheet!$A$2:$A$400,$T$32)/1000) | I32: =IF($T$32="","",SUMIFS(Mastersheet!$J$2:$J$400,Mastersheet!$A$2:$A$400,$T$32)/1000) | J32: =IF($T$32="","",SUMIFS(Mastersheet!$K$2:$K$400,Mastersheet!$A$2:$A$400,$T$32)/1000) | K32: =IF($T$32="","",SUMIFS(Mastersheet!$L$2:$L$400,Mastersheet!$A$2:$A$400,$T$32)/1000) | L32: =IF($T$32="","",SUMIFS(Mastersheet!$M$2:$M$400,Mastersheet!$A$2:$A$400,$T$32)/1000) | M32: =IF($T$32="","",SUMIFS(Mastersheet!$N$2:$N$400,Mastersheet!$A$2:$A$400,$T$32)/1000) | N32: =IF($T$32="","",SUMIFS(Mastersheet!$O$2:$O$400,Mastersheet!$A$2:$A$400,$T$32)/1000) | U32: Account | V32: KTO
E33: =IF($T$33="","",SUMIFS(Mastersheet!$F$2:$F$400,Mastersheet!$A$2:$A$400,$T$33)/1000) | F33: =IF($T$33="","",SUMIFS(Mastersheet!$G$2:$G$400,Mastersheet!$A$2:$A$400,$T$33)/1000) | G33: =IF($T$33="","",SUMIFS(Mastersheet!$H$2:$H$400,Mastersheet!$A$2:$A$400,$T$33)/1000) | H33: =IF($T$33="","",SUMIFS(Mastersheet!$I$2:$I$400,Mastersheet!$A$2:$A$400,$T$33)/1000) | I33: =IF($T$33="","",SUMIFS(Mastersheet!$J$2:$J$400,Mastersheet!$A$2:$A$400,$T$33)/1000) | J33: =IF($T$33="","",SUMIFS(Mastersheet!$K$2:$K$400,Mastersheet!$A$2:$A$400,$T$33)/1000) | K33: =IF($T$33="","",SUMIFS(Mastersheet!$L$2:$L$400,Mastersheet!$A$2:$A$400,$T$33)/1000) | L33: =IF($T$33="","",SUMIFS(Mastersheet!$M$2:$M$400,Mastersheet!$A$2:$A$400,$T$33)/1000) | M33: =IF($T$33="","",SUMIFS(Mastersheet!$N$2:$N$400,Mastersheet!$A$2:$A$400,$T$33)/1000) | N33: =IF($T$33="","",SUMIFS(Mastersheet!$O$2:$O$400,Mastersheet!$A$2:$A$400,$T$33)/1000) | U33: Account | V33: KTO
E34: =IF($T$34="","",SUMIFS(Mastersheet!$F$2:$F$400,Mastersheet!$A$2:$A$400,$T$34)/1000) | F34: =IF($T$34="","",SUMIFS(Mastersheet!$G$2:$G$400,Mastersheet!$A$2:$A$400,$T$34)/1000) | G34: =IF($T$34="","",SUMIFS(Mastersheet!$H$2:$H$400,Mastersheet!$A$2:$A$400,$T$34)/1000) | H34: =IF($T$34="","",SUMIFS(Mastersheet!$I$2:$I$400,Mastersheet!$A$2:$A$400,$T$34)/1000) | I34: =IF($T$34="","",SUMIFS(Mastersheet!$J$2:$J$400,Mastersheet!$A$2:$A$400,$T$34)/1000) | J34: =IF($T$34="","",SUMIFS(Mastersheet!$K$2:$K$400,Mastersheet!$A$2:$A$400,$T$34)/1000) | K34: =IF($T$34="","",SUMIFS(Mastersheet!$L$2:$L$400,Mastersheet!$A$2:$A$400,$T$34)/1000) | L34: =IF($T$34="","",SUMIFS(Mastersheet!$M$2:$M$400,Mastersheet!$A$2:$A$400,$T$34)/1000) | M34: =IF($T$34="","",SUMIFS(Mastersheet!$N$2:$N$400,Mastersheet!$A$2:$A$400,$T$34)/1000) | N34: =IF($T$34="","",SUMIFS(Mastersheet!$O$2:$O$400,Mastersheet!$A$2:$A$400,$T$34)/1000) | U34: Account | V34: KTO
E35: =IF($T$35="","",SUMIFS(Mastersheet!$F$2:$F$400,Mastersheet!$A$2:$A$400,$T$35)/1000) | F35: =IF($T$35="","",SUMIFS(Mastersheet!$G$2:$G$400,Mastersheet!$A$2:$A$400,$T$35)/1000) | G35: =IF($T$35="","",SUMIFS(Mastersheet!$H$2:$H$400,Mastersheet!$A$2:$A$400,$T$35)/1000) | H35: =IF($T$35="","",SUMIFS(Mastersheet!$I$2:$I$400,Mastersheet!$A$2:$A$400,$T$35)/1000) | I35: =IF($T$35="","",SUMIFS(Mastersheet!$J$2:$J$400,Mastersheet!$A$2:$A$400,$T$35)/1000) | J35: =IF($T$35="","",SUMIFS(Mastersheet!$K$2:$K$400,Mastersheet!$A$2:$A$400,$T$35)/1000) | K35: =IF($T$35="","",SUMIFS(Mastersheet!$L$2:$L$400,Mastersheet!$A$2:$A$400,$T$35)/1000) | L35: =IF($T$35="","",SUMIFS(Mastersheet!$M$2:$M$400,Mastersheet!$A$2:$A$400,$T$35)/1000) | M35: =IF($T$35="","",SUMIFS(Mastersheet!$N$2:$N$400,Mastersheet!$A$2:$A$400,$T$35)/1000) | N35: =IF($T$35="","",SUMIFS(Mastersheet!$O$2:$O$400,Mastersheet!$A$2:$A$400,$T$35)/1000) | U35: Account | V35: KTO
C36: Dummy 1 | D36: Dummy 1 | P36: =IFERROR(((H36/F36)^(1/(($H$1-$F$1)/365)))-1,"n/a") -> n/a | Q36: =IFERROR(((N36/H36)^(1/(($N$1-$H$1)/365)))-1,"n/a") -> n/a
C37: Dummy 2 | D37: Dummy 2 | P37: =IFERROR(((H37/F37)^(1/(($H$1-$F$1)/365)))-1,"n/a") -> n/a | Q37: =IFERROR(((N37/H37)^(1/(($N$1-$H$1)/365)))-1,"n/a") -> n/a
C38: Dummy 3 | D38: Dummy 3 | P38: =IFERROR(((H38/F38)^(1/(($H$1-$F$1)/365)))-1,"n/a") -> n/a | Q38: =IFERROR(((N38/H38)^(1/(($N$1-$H$1)/365)))-1,"n/a") -> n/a
C39: Gesamtleistung | D39: Total output | E39: =SUMIF($V$9:$V$38,"<>KTO",E9:E38) -> 0 | F39: =SUMIF($V$9:$V$38,"<>KTO",F9:F38) -> 0 | G39: =SUMIF($V$9:$V$38,"<>KTO",G9:G38) -> 0 | H39: =SUMIF($V$9:$V$38,"<>KTO",H9:H38) -> 0 | I39: =SUMIF($V$9:$V$38,"<>KTO",I9:I38) -> 0 | J39: =SUMIF($V$9:$V$38,"<>KTO",J9:J38) -> 0 | K39: =SUMIF($V$9:$V$38,"<>KTO",K9:K38) -> 0 | L39: =SUMIF($V$9:$V$38,"<>KTO",L9:L38) -> 0 | ... N39: =SUMIF($V$9:$V$38,"<>KTO",N9:N38) -> 0 | P39: =IFERROR(((H39/F39)^(1/(($H$1-$F$1)/365)))-1,"n/a") -> n/a | Q39: =IFERROR(((N39/H39)^(1/(($N$1-$H$1)/365)))-1,"n/a") -> n/a
C40: Materialaufwand | D40: Cost of materials | E40: =SUMIFS(Mastersheet!$F$2:$F$400,Mastersheet!$D$2:$D$400,$T40,Mastersheet!$C$2:$C$400,$U40)/1000 -> 0 | F40: =SUMIFS(Mastersheet!$G$2:$G$400,Mastersheet!$D$2:$D$400,$T40,Mastersheet!$C$2:$C$400,$U40)/1000 -> 0 | G40: =SUMIFS(Mastersheet!$H$2:$H$400,Mastersheet!$D$2:$D$400,$T40,Mastersheet!$C$2:$C$400,$U40)/1000 -> 0 | H40: =SUMIFS(Mastersheet!$I$2:$I$400,Mastersheet!$D$2:$D$400,$T40,Mastersheet!$C$2:$C$400,$U40)/1000 -> 0 | I40: =SUMIFS(Mastersheet!$J$2:$J$400,Mastersheet!$D$2:$D$400,$T40,Mastersheet!$C$2:$C$400,$U40)/1000 -> 0 | J40: =SUMIFS(Mastersheet!$K$2:$K$400,Mastersheet!$D$2:$D$400,$T40,Mastersheet!$C$2:$C$400,$U40)/1000 -> 0 | K40: =SUMIFS(Mastersheet!$L$2:$L$400,Mastersheet!$D$2:$D$400,$T40,Mastersheet!$C$2:$C$400,$U40)/1000 -> 0 | L40: =SUMIFS(Mastersheet!$M$2:$M$400,Mastersheet!$D$2:$D$400,$T40,Mastersheet!$C$2:$C$400,$U40)/1000 -> 0 | M40: =SUMIFS(Mastersheet!$N$2:$N$400,Mastersheet!$D$2:$D$400,$T40,Mastersheet!$C$2:$C$400,$U40)/1000 -> 0 | N40: =SUMIFS(Mastersheet!$O$2:$O$400,Mastersheet!$D$2:$D$400,$T40,Mastersheet!$C$2:$C$400,$U40)/1000 -> 0 | P40: =IFERROR(((H40/F40)^(1/(($H$1-$F$1)/365)))-1,"n/a") -> n/a | Q40: =IFERROR(((N40/H40)^(1/(($N$1-$H$1)/365)))-1,"n/a") -> n/a | T40: Materialaufwand | U40: PL | V40: POS
E41: =IF($T$41="","",SUMIFS(Mastersheet!$F$2:$F$400,Mastersheet!$A$2:$A$400,$T$41)/1000) | F41: =IF($T$41="","",SUMIFS(Mastersheet!$G$2:$G$400,Mastersheet!$A$2:$A$400,$T$41)/1000) | G41: =IF($T$41="","",SUMIFS(Mastersheet!$H$2:$H$400,Mastersheet!$A$2:$A$400,$T$41)/1000) | H41: =IF($T$41="","",SUMIFS(Mastersheet!$I$2:$I$400,Mastersheet!$A$2:$A$400,$T$41)/1000) | I41: =IF($T$41="","",SUMIFS(Mastersheet!$J$2:$J$400,Mastersheet!$A$2:$A$400,$T$41)/1000) | J41: =IF($T$41="","",SUMIFS(Mastersheet!$K$2:$K$400,Mastersheet!$A$2:$A$400,$T$41)/1000) | K41: =IF($T$41="","",SUMIFS(Mastersheet!$L$2:$L$400,Mastersheet!$A$2:$A$400,$T$41)/1000) | L41: =IF($T$41="","",SUMIFS(Mastersheet!$M$2:$M$400,Mastersheet!$A$2:$A$400,$T$41)/1000) | M41: =IF($T$41="","",SUMIFS(Mastersheet!$N$2:$N$400,Mastersheet!$A$2:$A$400,$T$41)/1000) | N41: =IF($T$41="","",SUMIFS(Mastersheet!$O$2:$O$400,Mastersheet!$A$2:$A$400,$T$41)/1000) | U41: Account | V41: KTO
E42: =IF($T$42="","",SUMIFS(Mastersheet!$F$2:$F$400,Mastersheet!$A$2:$A$400,$T$42)/1000) | F42: =IF($T$42="","",SUMIFS(Mastersheet!$G$2:$G$400,Mastersheet!$A$2:$A$400,$T$42)/1000) | G42: =IF($T$42="","",SUMIFS(Mastersheet!$H$2:$H$400,Mastersheet!$A$2:$A$400,$T$42)/1000) | H42: =IF($T$42="","",SUMIFS(Mastersheet!$I$2:$I$400,Mastersheet!$A$2:$A$400,$T$42)/1000) | I42: =IF($T$42="","",SUMIFS(Mastersheet!$J$2:$J$400,Mastersheet!$A$2:$A$400,$T$42)/1000) | J42: =IF($T$42="","",SUMIFS(Mastersheet!$K$2:$K$400,Mastersheet!$A$2:$A$400,$T$42)/1000) | K42: =IF($T$42="","",SUMIFS(Mastersheet!$L$2:$L$400,Mastersheet!$A$2:$A$400,$T$42)/1000) | L42: =IF($T$42="","",SUMIFS(Mastersheet!$M$2:$M$400,Mastersheet!$A$2:$A$400,$T$42)/1000) | M42: =IF($T$42="","",SUMIFS(Mastersheet!$N$2:$N$400,Mastersheet!$A$2:$A$400,$T$42)/1000) | N42: =IF($T$42="","",SUMIFS(Mastersheet!$O$2:$O$400,Mastersheet!$A$2:$A$400,$T$42)/1000) | U42: Account | V42: KTO
E43: =IF($T$43="","",SUMIFS(Mastersheet!$F$2:$F$400,Mastersheet!$A$2:$A$400,$T$43)/1000) | F43: =IF($T$43="","",SUMIFS(Mastersheet!$G$2:$G$400,Mastersheet!$A$2:$A$400,$T$43)/1000) | G43: =IF($T$43="","",SUMIFS(Mastersheet!$H$2:$H$400,Mastersheet!$A$2:$A$400,$T$43)/1000) | H43: =IF($T$43="","",SUMIFS(Mastersheet!$I$2:$I$400,Mastersheet!$A$2:$A$400,$T$43)/1000) | I43: =IF($T$43="","",SUMIFS(Mastersheet!$J$2:$J$400,Mastersheet!$A$2:$A$400,$T$43)/1000) | J43: =IF($T$43="","",SUMIFS(Mastersheet!$K$2:$K$400,Mastersheet!$A$2:$A$400,$T$43)/1000) | K43: =IF($T$43="","",SUMIFS(Mastersheet!$L$2:$L$400,Mastersheet!$A$2:$A$400,$T$43)/1000) | L43: =IF($T$43="","",SUMIFS(Mastersheet!$M$2:$M$400,Mastersheet!$A$2:$A$400,$T$43)/1000) | M43: =IF($T$43="","",SUMIFS(Mastersheet!$N$2:$N$400,Mastersheet!$A$2:$A$400,$T$43)/1000) | N43: =IF($T$43="","",SUMIFS(Mastersheet!$O$2:$O$400,Mastersheet!$A$2:$A$400,$T$43)/1000) | U43: Account | V43: KTO
...

Sheet Lead NA
C4: =Cockpit!$C$4 -> Template | E4: =Cockpit!C39 -> 44561 | F4: =Cockpit!D39 -> 44926 | G4: =Cockpit!E39 -> 45291 | H4: =Cockpit!F39 -> 45657 | I4: =Cockpit!G39 -> 45808 | J4: =Cockpit!H39 -> 46022 | K4: =Cockpit!I39 -> 46387 | L4: =Cockpit!J39 -> 46752 | M4: =Cockpit!K39 -> 47118
C5: ="in T"&Cockpit!$C$5 -> in TEUR | E5: IST | F5: IST | G5: IST | H5: IST | I5: IST | J5: =Cockpit!H40 -> Plan | K5: =Cockpit!I40 -> Plan | L5: =Cockpit!J40 -> Plan | M5: =Cockpit!K40 -> Plan | P5: Ticker 1 (NA-Zeile / Konto) | Q5: Ticker 2 (Klasse) | R5: Zeilentyp
D6: =Cockpit!$C$4 -> Template | E6: =Cockpit!C39 -> 44561 | F6: =Cockpit!D39 -> 44926 | G6: =Cockpit!E39 -> 45291 | H6: =Cockpit!F39 -> 45657 | I6: =Cockpit!G39 -> 45808 | J6: =Cockpit!H39 -> 46022 | K6: =Cockpit!I39 -> 46387 | L6: =Cockpit!J39 -> 46752 | M6: =Cockpit!K39 -> 47118
D7: ="in k"&Cockpit!$C$5 -> in kEUR | E7: =Cockpit!C40 -> IST | F7: =Cockpit!D40 -> IST | G7: =Cockpit!E40 -> IST | H7: =Cockpit!F40 -> IST | I7: =Cockpit!G40 -> IST | J7: =Cockpit!H40 -> Plan | K7: =Cockpit!I40 -> Plan | L7: =Cockpit!J40 -> Plan | M7: =Cockpit!K40 -> Plan | P7: Classification BT
