Workbook
Name ___mds_allowwriteback___: ""
Name ___mds_asyncwriteback___: FALSE
Name ___mds_first_cell___: #REF!
Name ___mds_last_dataset_cell__: "593~5"
Name ___mds_spreading___: FALSE
Name ___mds_view_data___: #REF!
Name _14N_0Umbuchun: [2]Anlagevermögen!#REF!
Name _15N_0Umbuchun: [2]Anlagevermögen!#REF!
Name _18N__Umbuchun: [2]Anlagevermögen!#REF!
Name _3_: [2]Anlagevermögen!#REF!
Name _8_0: [2]Anlagevermögen!#REF!
Name _9_0: [2]Anlagevermögen!#REF!
Name _DAT1: [3]Exportumsätze!#REF!
Name _DAT2: [3]Exportumsätze!#REF!
Name _DAT3: [3]Exportumsätze!#REF!
Name _DAT4: [3]Exportumsätze!#REF!
Name _DAT5: [3]Exportumsätze!#REF!
Name Art: #REF!
Name base_rate: #REF!
Name base_rate: #REF!
Name base_rate_monthly: #REF!
Name base_rate_monthly: #REF!
Name BraRepKumuliert: #REF!
Name cash_bf: #REF!
Name cash_bf: #REF!
Name cash_cf: #REF!
Name cash_cf: #REF!
Name completion: #REF!
Name completion: #REF!
Name Consultant_A: #REF!
Name Consultant_B: #REF!
Name ebitda: #REF!
Name ebitda: #REF!
Name exit_cash: #REF!
Name exit_cash: #REF!
Name exit_multiple: #REF!
Name exit_multiple: #REF!
Name exit_year: #REF!
Name exit_year: #REF!
Name gc_hint_new_document: #REF!
Name instrument_1: #REF!
Name instrument_1: #REF!
Name instrument_1_amount: #REF!
Name instrument_1_amount: #REF!
Name instrument_1_bf: #REF!
Name instrument_1_bf: #REF!
Name instrument_1_cf: #REF!
Name instrument_1_cf: #REF!
Name instrument_1_custom_pmt: #REF!
Name instrument_1_custom_pmt: #REF!
Name instrument_1_int_accrual: #REF!
Name instrument_1_int_accrual: #REF!
Name instrument_1_int_pmt: #REF!
Name instrument_1_int_pmt: #REF!
Name instrument_1_int_rate: #REF!
Name instrument_1_int_rate: #REF!
Name instrument_1_rollup: #REF!
Name instrument_1_rollup: #REF!
Name instrument_1_rollup_percent: #REF!
Name instrument_1_rollup_percent: #REF!

Sheet Disclaimer
B4: ="Project: "&Cockpit!C4 -> Project: Projekt Namur
B6: Status: Working Draft
B9: Databook Financial Due Diligence
B11: BakerTilly, #city#date#
B14: Disclaimer: This Databook is confidential and has been prepared exclusively for the benefit of the Client in connection with the Transaction and may not be disclosed, quoted, used or relied on for any other purpose or by any other party than the Client without the prior written consent of BT. This Databook is made available to the Client and we consent to the disclosure, provided that the client agress to non-reliance of this work-in-progress databook. Compensation claims of the Purchaser against BT for damages caused by negligence in connection with performance of the assignment are limited to EUR 4.000.000 (in words: Euro four million) for each damage event and for all damage events in total.

Sheet Cockpit
B3: Table labels | G3: = User Input
B4: Project name | C4: Projekt Namur
B5: Currency base code | C5: EUR | G5: = technische Hilfszelle --> nicht löschen
B7: Quelle: | C7: Datenraum/ eigene Analysen
B8: Source: | C8: Virtual Data Room/ Company Information
B10: Working Group
B11: Partner
B12: Manager
B13: Senior/Assistant
B16: Timeline parameter
B17: End of first historical period | C17: 44926
B18: Number of historical periods | C18: 3
B19: Label | C19: IST | D19: Adjust according to language(DEU/ ENG)
B21: CYT Begin Date | C21: 45658 | D21: =IF(C21<(EDATE(C17,24)),"CYT Begin Date must not be prior to historical date","ok") -> ok
B22: CYT Date | C22: 46022 | D22: =IF(TEXT($C$22,"TT.MM.")="31.12.","CYT date must not be December 31, check","ok") -> CYT date must not be December 31, check
B23: Label (Last twelve months) | C23: IST | D23: Aufgrund nachträglicher Datenlieferung LTM auf IST geändert, um weitere Änderung von Verlinkungen zu vermeiden
B24: Label (Current year trading) | C24: YTD
B25: Label (Year to go) | C25: YTG
B27: Label | C27: Plan
B31: Timeline (annual for PL and CF)
B32: Counter | D32: 1 | E32: =D32+1 -> 2 | F32: =E32+1 -> 3 | G32: =F32+1 -> 4 | H32: =G32+1 -> 5 | I32: =H32+1 -> 6 | J32: =I32+1 -> 7 | K32: =J32+1 -> 8 | L32: =K32+1 -> 9
B33: Date (Auto) | C33: =EDATE($C$17,-12) -> 44561 | D33: =IF(D$32<$C$18+1,EDATE($C$33,12*D$32),IF(OR(D$32=$C$18+1,D$32=$C$18+2),$C$22,IF(D$32>$C$18+2,EDATE($C$33,(D$32-2)*12)))) -> 44926 | E33: =IF(E$32<$C$18+1,EDATE($C$33,12*E$32),IF(OR(E$32=$C$18+1,E$32=$C$18+2),$C$22,IF(E$32>$C$18+2,EDATE($C$33,(E$32-2)*12)))) -> 45291 | F33: =IF(F$32<$C$18+1,EDATE($C$33,12*F$32),IF(OR(F$32=$C$18+1,F$32=$C$18+2),$C$22,IF(F$32>$C$18+2,EDATE($C$33,(F$32-2)*12)))) -> 45657 | G33: =IF(G$32<$C$18+1,EDATE($C$33,12*G$32),IF(OR(G$32=$C$18+1,G$32=$C$18+2),$C$22,IF(G$32>$C$18+2,EDATE($C$33,(G$32-2)*12)))) -> 46022 | H33: =IF(H$32<$C$18+1,EDATE($C$33,12*H$32),IF(OR(H$32=$C$18+1,H$32=$C$18+2),$C$22,IF(H$32>$C$18+2,EDATE($C$33,(H$32-2)*12)))) -> 46022 | I33: =IF(I$32<$C$18+1,EDATE($C$33,12*I$32),IF(OR(I$32=$C$18+1,I$32=$C$18+2),$C$22,IF(I$32>$C$18+2,EDATE($C$33,(I$32-2)*12)))) -> 46022 | J33: =IF(J$32<$C$18+1,EDATE($C$33,12*J$32),IF(OR(J$32=$C$18+1,J$32=$C$18+2),$C$22,IF(J$32>$C$18+2,EDATE($C$33,(J$32-2)*12)))) -> 46387 | K33: =IF(K$32<$C$18+1,EDATE($C$33,12*K$32),IF(OR(K$32=$C$18+1,K$32=$C$18+2),$C$22,IF(K$32>$C$18+2,EDATE($C$33,(K$32-2)*12)))) -> 46752 | L33: =IF(L$32<$C$18+1,EDATE($C$33,12*L$32),IF(OR(L$32=$C$18+1,L$32=$C$18+2),$C$22,IF(L$32>$C$18+2,EDATE($C$33,(L$32-2)*12)))) -> 47118
B34: Label | C34: =$C$19 -> IST | D34: =IF(D$32<=$C$18,$C$19,IF(D$32=$C$18+1,$C$23,IF(D$32=$C$18+2,$C$24,$C$27))) -> IST | E34: =IF(E$32<=$C$18,$C$19,IF(E$32=$C$18+1,$C$23,IF(E$32=$C$18+2,$C$24,$C$27))) -> IST | F34: =IF(F$32<=$C$18,$C$19,IF(F$32=$C$18+1,$C$23,IF(F$32=$C$18+2,$C$24,$C$27))) -> IST | G34: =IF(G$32<=$C$18,$C$19,IF(G$32=$C$18+1,$C$23,IF(G$32=$C$18+2,$C$24,$C$27))) -> IST | H34: =IF(H$32<=$C$18,$C$19,IF(H$32=$C$18+1,$C$23,IF(H$32=$C$18+2,$C$24,$C$27))) -> YTD | I34: =IF(I$32<=$C$18,$C$19,IF(I$32=$C$18+1,$C$23,IF(I$32=$C$18+2,$C$24,$C$27))) -> Plan | J34: =IF(J$32<=$C$18,$C$19,IF(J$32=$C$18+1,$C$23,IF(J$32=$C$18+2,$C$24,$C$27))) -> Plan | K34: =IF(K$32<=$C$18,$C$19,IF(K$32=$C$18+1,$C$23,IF(K$32=$C$18+2,$C$24,$C$27))) -> Plan | L34: =IF(L$32<=$C$18,$C$19,IF(L$32=$C$18+1,$C$23,IF(L$32=$C$18+2,$C$24,$C$27))) -> Plan
B37: Timeline (annual for BS)
B38: Counter | D38: 1 | E38: =D38+1 -> 2 | F38: =E38+1 -> 3 | G38: =F38+1 -> 4 | H38: =G38+1 -> 5 | I38: =H38+1 -> 6 | J38: =I38+1 -> 7 | K38: =J38+1 -> 8
B39: Date | C39: =EDATE($C$17,-12) -> 44561 | D39: =IF(D$38<$C$18+1,EDATE($C$39,12*D$38),IF(D$38=$C$18+1,$C$22,IF(D$38>$C$18+1,EDATE($C$39,(D$38-1)*12)))) -> 44926 | E39: =IF(E$38<$C$18+1,EDATE($C$39,12*E$38),IF(E$38=$C$18+1,$C$22,IF(E$38>$C$18+1,EDATE($C$39,(E$38-1)*12)))) -> 45291 | F39: =IF(F$38<$C$18+1,EDATE($C$39,12*F$38),IF(F$38=$C$18+1,$C$22,IF(F$38>$C$18+1,EDATE($C$39,(F$38-1)*12)))) -> 45657 | G39: =IF(G$38<$C$18+1,EDATE($C$39,12*G$38),IF(G$38=$C$18+1,$C$22,IF(G$38>$C$18+1,EDATE($C$39,(G$38-1)*12)))) -> 46022 | H39: =IF(H$38<$C$18+1,EDATE($C$39,12*H$38),IF(H$38=$C$18+1,$C$22,IF(H$38>$C$18+1,EDATE($C$39,(H$38-1)*12)))) -> 46022 | I39: =IF(I$38<$C$18+1,EDATE($C$39,12*I$38),IF(I$38=$C$18+1,$C$22,IF(I$38>$C$18+1,EDATE($C$39,(I$38-1)*12)))) -> 46387 | J39: =IF(J$38<$C$18+1,EDATE($C$39,12*J$38),IF(J$38=$C$18+1,$C$22,IF(J$38>$C$18+1,EDATE($C$39,(J$38-1)*12)))) -> 46752 | K39: =IF(K$38<$C$18+1,EDATE($C$39,12*K$38),IF(K$38=$C$18+1,$C$22,IF(K$38>$C$18+1,EDATE($C$39,(K$38-1)*12)))) -> 47118
B40: Label | C40: =$C$19 -> IST | D40: =IF(D$38<=$C$18,$C$19,IF(D$38=$C$18+1,$C$19,$C$27)) -> IST | E40: =IF(E$38<=$C$18,$C$19,IF(E$38=$C$18+1,$C$19,$C$27)) -> IST | F40: =IF(F$38<=$C$18,$C$19,IF(F$38=$C$18+1,$C$19,$C$27)) -> IST | G40: =IF(G$38<=$C$18,$C$19,IF(G$38=$C$18+1,$C$19,$C$27)) -> IST | H40: =IF(H$38<=$C$18,$C$19,IF(H$38=$C$18+1,$C$19,$C$27)) -> Plan | I40: =IF(I$38<=$C$18,$C$19,IF(I$38=$C$18+1,$C$19,$C$27)) -> Plan | J40: =IF(J$38<=$C$18,$C$19,IF(J$38=$C$18+1,$C$19,$C$27)) -> Plan | K40: =IF(K$38<=$C$18,$C$19,IF(K$38=$C$18+1,$C$19,$C$27)) -> Plan
B43: Timeline (monthly)
B44: Counter | D44: 1 | E44: =D44+1 -> 2 | F44: =E44+1 -> 3 | G44: =F44+1 -> 4 | H44: =G44+1 -> 5 | I44: =H44+1 -> 6 | J44: =I44+1 -> 7 | K44: =J44+1 -> 8 | L44: =K44+1 -> 9 | ... CI44: =CH44+1 -> 84
B45: Date | C45: =EDATE($C$17,-12) -> 44561 | D45: =EDATE($C$45,D$44) -> 44592 | E45: =EDATE($C$45,E$44) -> 44620 | F45: =EDATE($C$45,F$44) -> 44651 | G45: =EDATE($C$45,G$44) -> 44681 | H45: =EDATE($C$45,H$44) -> 44712 | I45: =EDATE($C$45,I$44) -> 44742 | J45: =EDATE($C$45,J$44) -> 44773 | K45: =EDATE($C$45,K$44) -> 44804 | ... CI45: =EDATE($C$45,CI$44) -> 47118
B46: Label | C46: =$C$19 -> IST | D46: =IF(D$45<=$C$22,$C$19,$C$27) -> IST | E46: =IF(E$45<=$C$22,$C$19,$C$27) -> IST | F46: =IF(F$45<=$C$22,$C$19,$C$27) -> IST | G46: =IF(G$45<=$C$22,$C$19,$C$27) -> IST | H46: =IF(H$45<=$C$22,$C$19,$C$27) -> IST | I46: =IF(I$45<=$C$22,$C$19,$C$27) -> IST | J46: =IF(J$45<=$C$22,$C$19,$C$27) -> IST | K46: =IF(K$45<=$C$22,$C$19,$C$27) -> IST | ... CI46: =IF(CI$45<=$C$22,$C$19,$C$27) -> Plan

Sheet Datengrundlage
B2: Deutsch: | F2: Manuell Anpassen
B3: =Cockpit!$C$4 -> Projekt Namur | C3: =Cockpit!D33 -> 44926 | D3: =Cockpit!E33 -> 45291 | E3: =Cockpit!F33 -> 45657 | F3: =Cockpit!G33 -> 46022
B6: Heinz Meise GmbH
B7: Jahresabschlüsse (geprüft) | C7: ja | D7: ja | E7: ja | F7: -
B8: Summen- und Saldenlisten (SuSas) - monatlich | C8: nein | D8: ja | E8: ja | F8: ja
B9: Betriebswirtschaftliche Auswertungen (BWAs) - monatlich | C9: ja | D9: ja | E9: ja | F9: ja
B10: Umsatzdaten und ausgewählte KPIs | C10: ja | D10: ja | E10: ja | F10: ja
B11: Detailaufrisse und Controlling-/ERP-Auswertungen | C11: ja | D11: ja | E11: ja | F11: nein
B12: Weitere Auskünfte zu ausgewählten Sachverhalten | D12: ja
B14: Entity 2
B15: Jahresabschlüsse (ungeprüft) | C15: ja | D15: ja | E15: ja | F15: -
B16: Summen- und Saldenlisten (SuSas) - monatlich | C16: ja | D16: ja | E16: ja | F16: ja
B17: Betriebswirtschaftliche Auswertungen (BWAs) - monatlich | C17: ja | D17: ja | E17: ja | F17: ja
B18: Umsatzdaten und ausgewählte KPIs | C18: ja | D18: ja | E18: ja | F18: ja
B19: Detailaufrisse und Controlling-/ERP-Auswertungen | C19: - | D19: - | E19: - | F19: -
B20: Weitere Auskünfte zu ausgewählten Sachverhalten | D20: ja
B22: Entity 3
B23: Jahresabschlüsse (ungeprüft) | C23: ja | D23: ja | E23: ja | F23: -
B24: Summen- und Saldenlisten (SuSas) - monatlich | C24: ja | D24: ja | E24: ja | F24: ja
B25: Betriebswirtschaftliche Auswertungen (BWAs) - monatlich | C25: ja | D25: ja | E25: ja | F25: ja
B26: Umsatzdaten und ausgewählte KPIs | C26: ja | D26: ja | E26: ja | F26: ja
B27: Detailaufrisse und Controlling-/ERP-Auswertungen | C27: - | D27: - | E27: - | F27: -
B28: Weitere Auskünfte zu ausgewählten Sachverhalten | D28: ja
B30: Entity 4
B31: Jahresabschlüsse (ungeprüft) | C31: ja | D31: ja | E31: ja | F31: -
B32: Summen- und Saldenlisten (SuSas) - monatlich | C32: ja | D32: ja | E32: ja | F32: ja
B33: Betriebswirtschaftliche Auswertungen (BWAs) - monatlich | C33: ja | D33: ja | E33: ja | F33: ja
B34: Umsatzdaten und ausgewählte KPIs | C34: ja | D34: ja | E34: ja | F34: ja
B35: Detailaufrisse und Controlling-/ERP-Auswertungen | C35: - | D35: - | E35: - | F35: -
B36: Weitere Auskünfte zu ausgewählten Sachverhalten | D36: ja
B38: ="Quelle: "&Cockpit!$C$7 -> Quelle: Datenraum/ eigene Analysen

Sheet Lead >>

Sheet Lead PL
C1: Technische Zeile --> nicht löschen | D1: Technische Zeile --> nicht löschen | E1: =IFERROR(E4,E6) -> 44561 | F1: =IFERROR(F4,F6) -> 44926 | G1: =IFERROR(G4,G6) -> 45291 | H1: =IFERROR(H4,H6) -> 45657 | I1: =IFERROR(I4,I6) -> 46022 | J1: =IFERROR(J4,J6) -> 46022 | K1: =IFERROR(K4,K6) -> 46022 | L1: =IFERROR(L4,L6) -> 46387 | ... N1: =IFERROR(N4,N6) -> 47118
G3: =G9/F9-1 -> -0.083355024 | H3: =H9/G9-1 -> 0.087731686 | I3: =I9/H9-1 -> -0.099053949
C4: =Cockpit!$C$4 -> Projekt Namur | E4: =Cockpit!C33 -> 44561 | F4: =Cockpit!D33 -> 44926 | G4: =Cockpit!E33 -> 45291 | H4: =Cockpit!F33 -> 45657 | I4: =Cockpit!G33 -> 46022 | J4: =Cockpit!H33 -> 46022 | K4: =Cockpit!I33 -> 46022 | L4: =Cockpit!J33 -> 46387 | ... N4: =Cockpit!L33 -> 47118 | P4: CAGR | Q4: CAGR
C5: ="in T"&Cockpit!$C$5 -> in TEUR | E5: =Cockpit!C34 -> IST | F5: =Cockpit!D34 -> IST | G5: =Cockpit!E34 -> IST | H5: =Cockpit!F34 -> IST | I5: =Cockpit!G34 -> IST | J5: =Cockpit!H34 -> YTD | K5: =Cockpit!I34 -> Plan | L5: =Cockpit!J34 -> Plan | ... N5: =Cockpit!L34 -> Plan | P5: IST | Q5: =Cockpit!$C$27 -> Plan
D6: =Cockpit!$C$4 -> Projekt Namur | E6: =Cockpit!C33 -> 44561 | F6: =Cockpit!D33 -> 44926 | G6: =Cockpit!E33 -> 45291 | H6: =Cockpit!F33 -> 45657 | I6: =Cockpit!G33 -> 46022 | J6: =Cockpit!H33 -> 46022 | K6: =Cockpit!I33 -> 46022 | L6: =Cockpit!J33 -> 46387 | ... N6: =Cockpit!L33 -> 47118 | P6: CAGR | Q6: CAGR
D7: ="in k"&Cockpit!$C$5 -> in kEUR | E7: =Cockpit!C34 -> IST | F7: =Cockpit!D34 -> IST | G7: =Cockpit!E34 -> IST | H7: =Cockpit!F34 -> IST | I7: =Cockpit!G34 -> IST | J7: =Cockpit!H34 -> YTD | K7: =Cockpit!I34 -> Plan | L7: =Cockpit!J34 -> Plan | ... N7: =Cockpit!L34 -> Plan | P7: =Cockpit!$C$19 -> IST | Q7: =Cockpit!$C$27 -> Plan | T7: Classification BT
C9: Umsatzerlöse | D9: Revenues | F9: ='P&L (Annual Report)'!E23/1000 -> 16709.025 | G9: =-SUMIF('Trial Balance (Susa)'!D:D,"*"&$T9&"*",'Trial Balance (Susa)'!G:G)/1000 -> 15316.244 | H9: =-SUMIF('Trial Balance (Susa)'!D:D,"*"&$T9&"*",'Trial Balance (Susa)'!H:H)/1000 -> 16659.963 | I9: =-SUMIF('Trial Balance (Susa)'!D:D,"*"&$T9&"*",'Trial Balance (Susa)'!I:I)/1000 -> 15009.728 | J9: =-SUMIF('Trial Balance (Susa)'!D:D,"*"&$T9&"*",'Trial Balance (Susa)'!J:J)/1000 -> 0 | P9: =IFERROR(((H9/F9)^(1/(($H$1-$F$1)/365)))-1,"n/a") -> -0.0014671778 | Q9: =IFERROR(((N9/H9)^(1/(($N$1-$H$1)/365)))-1,"n/a") -> -1 | T9: /profit and loss/income/sales
C10: Erlöse Produktion | F10: ='P&L (Annual Report)'!E11/1000+3534.5 -> 9038.8983 | G10: =-'Trial Balance (Susa)'!G305/1000+2617 -> 9106.0935 | H10: =-'Trial Balance (Susa)'!H305/1000+4348.5 -> 11306.728 | I10: =-'Trial Balance (Susa)'!I305/1000 -> 6124.283 | T10: Produktion | V10: Check Verlinkungen der Umsatzerlöse und Umgliederung aus nicht steuerbaren Umsätzen
C11: Erlöse Handel | F11: ='P&L (Annual Report)'!E12/1000+62.6 -> 7415.4844 | G11: =-SUM('Trial Balance (Susa)'!G306)/1000+66.1 -> 6054.461 | H11: =-SUM('Trial Balance (Susa)'!H306)/1000+6 -> 5076.7472 | I11: =-SUM('Trial Balance (Susa)'!I306)/1000 -> 4016.1017 | T11: Handel
C12: Erlöse Dienstleistung | F12: =SUM(F13:F17) -> 457.76717 | G12: =SUM(G13:G17) -> 364.8482 | H12: =SUM(H13:H17) -> 452.93157 | I12: =SUM(I13:I17) -> 191.98364
C13: Erlöse Sterilisation | F13: ='P&L (Annual Report)'!E13/1000+243.5 -> 323.4889 | G13: =-SUM('Trial Balance (Susa)'!G307)/1000+172.5 -> 249.6488 | H13: =-SUM('Trial Balance (Susa)'!H307)/1000+236.8 -> 318.06137 | I13: =-SUM('Trial Balance (Susa)'!I307)/1000 -> 96.27319 | T13: Sterilisation
C14: Erlöse Wartung | F14: ='P&L (Annual Report)'!E14/1000 -> 50.2274 | G14: =-SUM('Trial Balance (Susa)'!G308)/1000 -> 64.5155 | H14: =-SUM('Trial Balance (Susa)'!H308)/1000 -> 88.5138 | I14: =-SUM('Trial Balance (Susa)'!I308)/1000 -> 63.3968 | T14: Wartung
C15: Erlöse Miete | F15: ='P&L (Annual Report)'!E15/1000 -> 42.77582 | G15: =-SUM('Trial Balance (Susa)'!G309)/1000 -> 48.32 | H15: =-SUM('Trial Balance (Susa)'!H309)/1000 -> 41.699 | I15: =-SUM('Trial Balance (Susa)'!I309)/1000 -> 28.8433 | T15: Miete
C16: Erlöse Abfallverwertung | F16: ='P&L (Annual Report)'!E16/1000 -> 2.29225 | G16: =-SUM('Trial Balance (Susa)'!G310)/1000 -> 1.3954 | H16: =-SUM('Trial Balance (Susa)'!H310)/1000 -> 3.4574 | I16: =-SUM('Trial Balance (Susa)'!I310)/1000 -> 3.0796 | T16: Abfall
C17: Sonstige Erlöse | F17: ='P&L (Annual Report)'!E7/1000+38.6 -> 38.9828 | G17: =-'Trial Balance (Susa)'!G302/1000+0.5 -> 0.9685 | H17: =-'Trial Balance (Susa)'!H302/1000+0.6 -> 1.2 | I17: =-'Trial Balance (Susa)'!I302/1000 -> 0.39075 | T17: Sonstige Dienstleistung
C18: Skonti und Boni | F18: {=SUM('P&L (Annual Report)'!E17:E22/1000)} -> -202.80217 | G18: =-('Trial Balance (Susa)'!G315+'Trial Balance (Susa)'!G316+'Trial Balance (Susa)'!G317+'Trial Balance (Susa)'!G318+'Trial Balance (Susa)'!G319)/1000 -> -207.36748 | H18: =-('Trial Balance (Susa)'!H315+'Trial Balance (Susa)'!H316+'Trial Balance (Susa)'!H317+'Trial Balance (Susa)'!H318+'Trial Balance (Susa)'!H319)/1000 -> -172.40615 | I18: =-('Trial Balance (Susa)'!I315+'Trial Balance (Susa)'!I316+'Trial Balance (Susa)'!I317+'Trial Balance (Susa)'!I318+'Trial Balance (Susa)'!I319)/1000 -> -167.08108 | T18: Skonti
C19: Bestandsveränderung | D19: Change in inventory | F19: ='P&L (Annual Report)'!E28/1000 -> -292.27995 | G19: =-SUMIF('Trial Balance (Susa)'!D:D,"*"&$T19&"*",'Trial Balance (Susa)'!G:G)/1000 -> 199.57713 | H19: =-SUMIF('Trial Balance (Susa)'!D:D,"*"&$T19&"*",'Trial Balance (Susa)'!H:H)/1000 -> 350.79514 | I19: =-SUMIF('Trial Balance (Susa)'!D:D,"*"&$T19&"*",'Trial Balance (Susa)'!I:I)/1000 -> 226.19016 | J19: =-SUMIF('Trial Balance (Susa)'!D:D,"*"&$T19&"*",'Trial Balance (Susa)'!J:J)/1000 -> 0 | P19: =IFERROR(((H19/F19)^(1/(($H$1-$F$1)/365)))-1,"n/a") -> n/a | Q19: =IFERROR(((N19/H19)^(1/(($N$1-$H$1)/365)))-1,"n/a") -> -1 | T19: /profit and loss/income/increase in inventory
C20: Aktivierte Eigenleistungen | D20: Own work capitalized | G20: =-SUMIF('Trial Balance (Susa)'!D:D,"*"&$T20&"*",'Trial Balance (Susa)'!G:G)/1000 -> 0 | H20: =-SUMIF('Trial Balance (Susa)'!D:D,"*"&$T20&"*",'Trial Balance (Susa)'!H:H)/1000 -> 0 | I20: =-SUMIF('Trial Balance (Susa)'!D:D,"*"&$T20&"*",'Trial Balance (Susa)'!I:I)/1000 -> 0 | J20: =-SUMIF('Trial Balance (Susa)'!D:D,"*"&$T20&"*",'Trial Balance (Susa)'!J:J)/1000 -> 0 | P20: =IFERROR(((H20/F20)^(1/(($H$1-$F$1)/365)))-1,"n/a") -> n/a | Q20: =IFERROR(((N20/H20)^(1/(($N$1-$H$1)/365)))-1,"n/a") -> n/a | T20: /profit and loss/income/own work capitalised
C21: Dummy 1 | D21: Dummy 1 | P21: =IFERROR(((H21/F21)^(1/(($H$1-$F$1)/365)))-1,"n/a") -> n/a | Q21: =IFERROR(((N21/H21)^(1/(($N$1-$H$1)/365)))-1,"n/a") -> n/a
C22: Dummy 2 | D22: Dummy 2 | P22: =IFERROR(((H22/F22)^(1/(($H$1-$F$1)/365)))-1,"n/a") -> n/a | Q22: =IFERROR(((N22/H22)^(1/(($N$1-$H$1)/365)))-1,"n/a") -> n/a
C23: Dummy 3 | D23: Dummy 3 | P23: =IFERROR(((H23/F23)^(1/(($H$1-$F$1)/365)))-1,"n/a") -> n/a | Q23: =IFERROR(((N23/H23)^(1/(($N$1-$H$1)/365)))-1,"n/a") -> n/a
C24: Gesamtleistung | D24: Total output | E24: =SUM(E9:E23) -> 0 | F24: =F9+F19 -> 16416.745 | G24: =G9+G19 -> 15515.821 | H24: =H9+H19 -> 17010.759 | I24: =I9+I19 -> 15235.918 | J24: =SUM(J9:J23) -> 0 | K24: =SUM(K9:K23) -> 0 | L24: =SUM(L9:L23) -> 0 | M24: =SUM(M9:M23) -> 0 | N24: =SUM(N9:N23) -> 0 | P24: =IFERROR(((H24/F24)^(1/(($H$1-$F$1)/365)))-1,"n/a") -> 0.017906198 | Q24: =IFERROR(((N24/H24)^(1/(($N$1-$H$1)/365)))-1,"n/a") -> -1
C25: Materialaufwand | D25: Cost of materials | F25: =-'P&L (Annual Report)'!E66/1000 -> -7633.1262 | G25: =-SUMIF('Trial Balance (Susa)'!D:D,"*"&$T25&"*",'Trial Balance (Susa)'!G:G)/1000 -> -8086.5024 | H25: =-SUMIF('Trial Balance (Susa)'!D:D,"*"&$T25&"*",'Trial Balance (Susa)'!H:H)/1000 -> -8397.8874 | I25: =-SUMIF('Trial Balance (Susa)'!D:D,"*"&$T25&"*",'Trial Balance (Susa)'!I:I)/1000 -> -7361.7847 | J25: =-SUMIF('Trial Balance (Susa)'!D:D,"*"&$T25&"*",'Trial Balance (Susa)'!J:J)/1000 -> 0 | P25: =IFERROR(((H25/F25)^(1/(($H$1-$F$1)/365)))-1,"n/a") -> 0.048830815 | Q25: =IFERROR(((N25/H25)^(1/(($N$1-$H$1)/365)))-1,"n/a") -> -1 | T25: /profit and loss/expense/material expense
C26: RHB-Aufwand | D26: Dummy 1 | F26: =-SUM('Trial Balance (Susa)'!E99,'Trial Balance (Susa)'!E104:E113)/1000 -> -7148.9266 | G26: =-SUM('Trial Balance (Susa)'!G99,'Trial Balance (Susa)'!G104:G113)/1000 -> -7440.4885 | H26: =-SUM('Trial Balance (Susa)'!H99,'Trial Balance (Susa)'!H104:H113)/1000 -> -7745.9163 | I26: =-SUM('Trial Balance (Susa)'!I99,'Trial Balance (Susa)'!I104:I113)/1000 -> -6854.7081 | P26: =IFERROR(((H26/F26)^(1/(($H$1-$F$1)/365)))-1,"n/a") -> 0.040859614 | Q26: =IFERROR(((N26/H26)^(1/(($N$1-$H$1)/365)))-1,"n/a") -> -1
C27: Fremdleistungen | D27: Dummy 2 | F27: =-SUM('Trial Balance (Susa)'!E100:E103)/1000 -> -484.19962 | G27: =-SUM('Trial Balance (Susa)'!G100:G103)/1000 -> -646.01391 | H27: =-SUM('Trial Balance (Susa)'!H100:H103)/1000 -> -651.97105 | I27: =-SUM('Trial Balance (Susa)'!I100:I103)/1000 -> -507.07659 | P27: =IFERROR(((H27/F27)^(1/(($H$1-$F$1)/365)))-1,"n/a") -> 0.16014844 | Q27: =IFERROR(((N27/H27)^(1/(($N$1-$H$1)/365)))-1,"n/a") -> -1
C28: Dummy 3 | D28: Dummy 3 | P28: =IFERROR(((H28/F28)^(1/(($H$1-$F$1)/365)))-1,"n/a") -> n/a | Q28: =IFERROR(((N28/H28)^(1/(($N$1-$H$1)/365)))-1,"n/a") -> n/a
C29: Rohergebnis | D29: Gross profit | E29: =SUM(E24:E28) -> 0 | F29: =SUM(F24:F28) -> 1150.4924 | G29: =SUM(G24:G28) -> -657.18405 | H29: =SUM(H24:H28) -> 214.98382 | I29: =SUM(I24:I28) -> 512.34907 | J29: =SUM(J24:J28) -> 0 | K29: =SUM(K24:K28) -> 0 | L29: =SUM(L24:L28) -> 0 | ... N29: =SUM(N24:N28) -> 0 | P29: =IFERROR(((H29/F29)^(1/(($H$1-$F$1)/365)))-1,"n/a") -> -0.56722787 | Q29: =IFERROR(((N29/H29)^(1/(($N$1-$H$1)/365)))-1,"n/a") -> -1
C30: Personalaufwand | D30: Personnel expenses | F30: =-'P&L (Annual Report)'!E96/1000 -> -3564.1972 | G30: =-SUMIF('Trial Balance (Susa)'!D:D,"*"&$T30&"*",'Trial Balance (Susa)'!G:G)/1000 -> -3758.9843 | H30: =-SUMIF('Trial Balance (Susa)'!D:D,"*"&$T30&"*",'Trial Balance (Susa)'!H:H)/1000 -> -4522.3511 | I30: =-SUMIF('Trial Balance (Susa)'!D:D,"*"&$T30&"*",'Trial Balance (Susa)'!I:I)/1000 -> -4225.827 | J30: =-SUMIF('Trial Balance (Susa)'!D:D,"*"&$T30&"*",'Trial Balance (Susa)'!J:J)/1000 -> 0 | P30: =IFERROR(((H30/F30)^(1/(($H$1-$F$1)/365)))-1,"n/a") -> 0.12623896 | Q30: =IFERROR(((N30/H30)^(1/(($N$1-$H$1)/365)))-1,"n/a") -> -1 | T30: /profit and loss/expense/personnel expense
C31: Miet- und Grundstücksaufwendungen | D31: Premise costs | F31: =-'P&L (Annual Report)'!E102/1000-'P&L (Annual Report)'!E104/1000 -> -346.10809 | G31: =-SUMIF('Trial Balance (Susa)'!D:D,"*"&$T31&"*",'Trial Balance (Susa)'!G:G)/1000 -> -341.33094 | H31: =-SUMIF('Trial Balance (Susa)'!D:D,"*"&$T31&"*",'Trial Balance (Susa)'!H:H)/1000 -> -422.98253 | I31: =-SUMIF('Trial Balance (Susa)'!D:D,"*"&$T31&"*",'Trial Balance (Susa)'!I:I)/1000 -> -349.32933 | J31: =-SUMIF('Trial Balance (Susa)'!D:D,"*"&$T31&"*",'Trial Balance (Susa)'!J:J)/1000 -> 0 | P31: =IFERROR(((H31/F31)^(1/(($H$1-$F$1)/365)))-1,"n/a") -> 0.10533967 | Q31: =IFERROR(((N31/H31)^(1/(($N$1-$H$1)/365)))-1,"n/a") -> -1 | T31: /profit and loss/expense/other expense/premise costs
C32: Reparaturen und Instandhaltungen | D32: Repair and maintenance | F32: =-'P&L (Annual Report)'!E112/1000 -> -117.49203 | G32: =-SUMIF('Trial Balance (Susa)'!D:D,"*"&$T32&"*",'Trial Balance (Susa)'!G:G)/1000 -> -124.28149 | H32: =-SUMIF('Trial Balance (Susa)'!D:D,"*"&$T32&"*",'Trial Balance (Susa)'!H:H)/1000 -> -133.31281 | I32: =-SUMIF('Trial Balance (Susa)'!D:D,"*"&$T32&"*",'Trial Balance (Susa)'!I:I)/1000 -> -112.53349 | J32: =-SUMIF('Trial Balance (Susa)'!D:D,"*"&$T32&"*",'Trial Balance (Susa)'!J:J)/1000 -> 0 | P32: =IFERROR(((H32/F32)^(1/(($H$1-$F$1)/365)))-1,"n/a") -> 0.065109385 | Q32: =IFERROR(((N32/H32)^(1/(($N$1-$H$1)/365)))-1,"n/a") -> -1 | T32: /profit and loss/expense/other expense/repair and maintenance
C33: Vertriebskosten | D33: Sales costs | F33: 0 | G33: =-SUMIF('Trial Balance (Susa)'!D:D,"*"&$T33&"*",'Trial Balance (Susa)'!G:G)/1000 -> 0 | H33: =-SUMIF('Trial Balance (Susa)'!D:D,"*"&$T33&"*",'Trial Balance (Susa)'!H:H)/1000 -> 0 | I33: =-SUMIF('Trial Balance (Susa)'!D:D,"*"&$T33&"*",'Trial Balance (Susa)'!I:I)/1000 -> 0 | J33: =-SUMIF('Trial Balance (Susa)'!D:D,"*"&$T33&"*",'Trial Balance (Susa)'!J:J)/1000 -> 0 | P33: =IFERROR(((H33/F33)^(1/(($H$1-$F$1)/365)))-1,"n/a") -> n/a | Q33: =IFERROR(((N33/H33)^(1/(($N$1-$H$1)/365)))-1,"n/a") -> n/a | T33: /profit and loss/expense/other expense/sales costs
C34: Kosten der Warenabgabe | D34: Delivery costs | F34: =-'P&L (Annual Report)'!E183/1000 -> -341.11215 | G34: =-SUMIF('Trial Balance (Susa)'!D:D,"*"&$T34&"*",'Trial Balance (Susa)'!G:G)/1000 -> -285.42781 | H34: =-SUMIF('Trial Balance (Susa)'!D:D,"*"&$T34&"*",'Trial Balance (Susa)'!H:H)/1000 -> -301.38343 | I34: =-SUMIF('Trial Balance (Susa)'!D:D,"*"&$T34&"*",'Trial Balance (Susa)'!I:I)/1000 -> -355.58784 | J34: =-SUMIF('Trial Balance (Susa)'!D:D,"*"&$T34&"*",'Trial Balance (Susa)'!J:J)/1000 -> 0 | P34: =IFERROR(((H34/F34)^(1/(($H$1-$F$1)/365)))-1,"n/a") -> -0.059956664 | Q34: =IFERROR(((N34/H34)^(1/(($N$1-$H$1)/365)))-1,"n/a") -> -1 | T34: /profit and loss/expense/other expense/delivery costs
C35: Fahrzeugkosten | D35: Vehicle costs | F35: =-'P&L (Annual Report)'!E164/1000 -> -184.66753 | G35: =-SUMIF('Trial Balance (Susa)'!D:D,"*"&$T35&"*",'Trial Balance (Susa)'!G:G)/1000 -> -194.66808 | H35: =-SUMIF('Trial Balance (Susa)'!D:D,"*"&$T35&"*",'Trial Balance (Susa)'!H:H)/1000 -> -246.06181 | I35: =-SUMIF('Trial Balance (Susa)'!D:D,"*"&$T35&"*",'Trial Balance (Susa)'!I:I)/1000 -> -239.94903 | J35: =-SUMIF('Trial Balance (Susa)'!D:D,"*"&$T35&"*",'Trial Balance (Susa)'!J:J)/1000 -> 0 | P35: =IFERROR(((H35/F35)^(1/(($H$1-$F$1)/365)))-1,"n/a") -> 0.15409504 | Q35: =IFERROR(((N35/H35)^(1/(($N$1-$H$1)/365)))-1,"n/a") -> -1 | T35: /profit and loss/expense/other expense/vehicle costs
C36: Versicherung, Beiträge und Abgaben | D36: Insurance, contributions and levies expenses | F36: =-'P&L (Annual Report)'!E108/1000 -> -62.46609 | G36: =-SUMIF('Trial Balance (Susa)'!D:D,"*"&$T36&"*",'Trial Balance (Susa)'!G:G)/1000 -> -73.2431 | H36: =-SUMIF('Trial Balance (Susa)'!D:D,"*"&$T36&"*",'Trial Balance (Susa)'!H:H)/1000 -> -69.6834 | I36: =-SUMIF('Trial Balance (Susa)'!D:D,"*"&$T36&"*",'Trial Balance (Susa)'!I:I)/1000 -> -69.77079 | J36: =-SUMIF('Trial Balance (Susa)'!D:D,"*"&$T36&"*",'Trial Balance (Susa)'!J:J)/1000 -> 0 | P36: =IFERROR(((H36/F36)^(1/(($H$1-$F$1)/365)))-1,"n/a") -> 0.056112117 | Q36: =IFERROR(((N36/H36)^(1/(($N$1-$H$1)/365)))-1,"n/a") -> -1 | T36: /profit and loss/expense/other expense/insurance contributions and levies
C37: Werbe- und Reisekosten | D37: Advertising and travel expenses | F37: =-'P&L (Annual Report)'!E178/1000 -> -140.85126 | G37: =-SUMIF('Trial Balance (Susa)'!D:D,"*"&$T37&"*",'Trial Balance (Susa)'!G:G)/1000 -> -177.41994 | H37: =-SUMIF('Trial Balance (Susa)'!D:D,"*"&$T37&"*",'Trial Balance (Susa)'!H:H)/1000 -> -154.10663 | I37: =-SUMIF('Trial Balance (Susa)'!D:D,"*"&$T37&"*",'Trial Balance (Susa)'!I:I)/1000 -> -163.61566 | J37: =-SUMIF('Trial Balance (Susa)'!D:D,"*"&$T37&"*",'Trial Balance (Susa)'!J:J)/1000 -> 0 | P37: =IFERROR(((H37/F37)^(1/(($H$1-$F$1)/365)))-1,"n/a") -> 0.045932303 | Q37: =IFERROR(((N37/H37)^(1/(($N$1-$H$1)/365)))-1,"n/a") -> -1 | T37: /profit and loss/expense/other expense/advertising and travel
C38: Sonstige betriebliche Erträge | D38: Other operating income | F38: ='P&L (Annual Report)'!E45/1000 -> 243.1056 | G38: =-SUMIF('Trial Balance (Susa)'!D:D,"*"&$T38&"*",'Trial Balance (Susa)'!G:G)/1000 -> 186.95985 | H38: =-SUMIF('Trial Balance (Susa)'!D:D,"*"&$T38&"*",'Trial Balance (Susa)'!H:H)/1000 -> 264.5716 | I38: =-SUMIF('Trial Balance (Susa)'!D:D,"*"&$T38&"*",'Trial Balance (Susa)'!I:I)/1000 -> 185.38533 | J38: =-SUMIF('Trial Balance (Susa)'!D:D,"*"&$T38&"*",'Trial Balance (Susa)'!J:J)/1000 -> 0 | P38: =IFERROR(((H38/F38)^(1/(($H$1-$F$1)/365)))-1,"n/a") -> 0.043155362 | Q38: =IFERROR(((N38/H38)^(1/(($N$1-$H$1)/365)))-1,"n/a") -> -1 | T38: /profit and loss/income/other income
C39: Sonstige betriebliche Aufwendungen | D39: Other operating expenses | F39: =-SUM('P&L (Annual Report)'!E201,'P&L (Annual Report)'!E207,'P&L (Annual Report)'!E211,'P&L (Annual Report)'!E213)/1000 -> -1023.4058 | G39: =-SUMIF('Trial Balance (Susa)'!D:D,"*"&$T39&"*",'Trial Balance (Susa)'!G:G)/1000 -> -1065.7626 | H39: =-SUMIF('Trial Balance (Susa)'!D:D,"*"&$T39&"*",'Trial Balance (Susa)'!H:H)/1000 -> -1267.2204 | I39: =-SUMIF('Trial Balance (Susa)'!D:D,"*"&$T39&"*",'Trial Balance (Susa)'!I:I)/1000 -> -1226.4219 | J39: =-SUMIF('Trial Balance (Susa)'!D:D,"*"&$T39&"*",'Trial Balance (Susa)'!J:J)/1000 -> 0 | P39: =IFERROR(((H39/F39)^(1/(($H$1-$F$1)/365)))-1,"n/a") -> 0.11259898 | Q39: =IFERROR(((N39/H39)^(1/(($N$1-$H$1)/365)))-1,"n/a") -> -1 | T39: /profit and loss/expense/other expense/other operating expense
C40: Dummy 1 | D40: Dummy 1 | P40: =IFERROR(((H40/F40)^(1/(($H$1-$F$1)/365)))-1,"n/a") -> n/a | Q40: =IFERROR(((N40/H40)^(1/(($N$1-$H$1)/365)))-1,"n/a") -> n/a
C41: Dummy 2 | D41: Dummy 2 | P41: =IFERROR(((H41/F41)^(1/(($H$1-$F$1)/365)))-1,"n/a") -> n/a | Q41: =IFERROR(((N41/H41)^(1/(($N$1-$H$1)/365)))-1,"n/a") -> n/a
C42: Dummy 3 | D42: Dummy 3 | P42: =IFERROR(((H42/F42)^(1/(($H$1-$F$1)/365)))-1,"n/a") -> n/a | Q42: =IFERROR(((N42/H42)^(1/(($N$1-$H$1)/365)))-1,"n/a") -> n/a
...

Sheet Lead NA
C4: =Cockpit!$C$4 -> Projekt Namur | E4: =Cockpit!C39 -> 44561 | F4: =Cockpit!D39 -> 44926 | G4: =Cockpit!E39 -> 45291 | H4: =Cockpit!F39 -> 45657 | I4: =Cockpit!G39 -> 46022 | J4: =Cockpit!H39 -> 46022 | K4: =Cockpit!I39 -> 46387 | L4: =Cockpit!J39 -> 46752 | M4: =Cockpit!K39 -> 47118
C5: ="in T"&Cockpit!$C$5 -> in TEUR | E5: IST | F5: IST | G5: IST | H5: IST | I5: IST | J5: =Cockpit!H40 -> Plan | K5: =Cockpit!I40 -> Plan | L5: =Cockpit!J40 -> Plan | M5: =Cockpit!K40 -> Plan
D6: =Cockpit!$C$4 -> Projekt Namur | E6: =Cockpit!C39 -> 44561 | F6: =Cockpit!D39 -> 44926 | G6: =Cockpit!E39 -> 45291 | H6: =Cockpit!F39 -> 45657 | I6: =Cockpit!G39 -> 46022 | J6: =Cockpit!H39 -> 46022 | K6: =Cockpit!I39 -> 46387 | L6: =Cockpit!J39 -> 46752 | M6: =Cockpit!K39 -> 47118
D7: ="in k"&Cockpit!$C$5 -> in kEUR | E7: =Cockpit!C40 -> IST | F7: =Cockpit!D40 -> IST | G7: =Cockpit!E40 -> IST | H7: =Cockpit!F40 -> IST | I7: =Cockpit!G40 -> IST | J7: =Cockpit!H40 -> Plan | K7: =Cockpit!I40 -> Plan | L7: =Cockpit!J40 -> Plan | M7: =Cockpit!K40 -> Plan | P7: Classification BT
C9: Immaterielle Vermögensgegenstände | D9: Intangible assets | F9: ='Balance Sheet (Annual Report)'!E7/1000 -> 6.154 | G9: =SUMIF('Trial Balance (Susa)'!D:D,"*"&$P9&"*",'Trial Balance (Susa)'!G:G)/1000 -> 3.606 | H9: =SUMIF('Trial Balance (Susa)'!D:D,"*"&$P9&"*",'Trial Balance (Susa)'!H:H)/1000 -> 204.27617 | I9: =SUMIF('Trial Balance (Susa)'!D:D,"*"&$P9&"*",'Trial Balance (Susa)'!I:I)/1000 -> 666.00327 | P9: /fixed assets/intangible assets
C10: Sachanlagen | D10: Tangible assets | F10: ='Balance Sheet (Annual Report)'!E17/1000 -> 980.837 | G10: =SUMIF('Trial Balance (Susa)'!D:D,"*"&$P10&"*",'Trial Balance (Susa)'!G:G)/1000 -> 715.176 | H10: =SUMIF('Trial Balance (Susa)'!D:D,"*"&$P10&"*",'Trial Balance (Susa)'!H:H)/1000 -> 826.464 | I10: =SUMIF('Trial Balance (Susa)'!D:D,"*"&$P10&"*",'Trial Balance (Susa)'!I:I)/1000 -> 600.385 | P10: /fixed assets/tangible assets
C11: Finanzanlagen | D11: Financial assets | F11: ='Balance Sheet (Annual Report)'!E22/1000 -> 206.89412 | G11: =SUMIF('Trial Balance (Susa)'!D:D,"*"&$P11&"*",'Trial Balance (Susa)'!G:G)/1000 -> 182.17891 | H11: =SUMIF('Trial Balance (Susa)'!D:D,"*"&$P11&"*",'Trial Balance (Susa)'!H:H)/1000 -> 75.42562 | I11: =SUMIF('Trial Balance (Susa)'!D:D,"*"&$P11&"*",'Trial Balance (Susa)'!I:I)/1000 -> 121.96562 | P11: /fixed assets/financial assets
C12: Dummy 1 | D12: Dummy 1
C13: Dummy 2 | D13: Dummy 2
C14: Dummy 3 | D14: Dummy 3
C15: Anlagevermögen | D15: Fixed assets | E15: =SUM(E9:E14) -> 0 | F15: =SUM(F9:F14) -> 1193.8851 | G15: =SUM(G9:G14) -> 900.96091 | H15: =SUM(H9:H14) -> 1106.1658 | I15: =SUM(I9:I14) -> 1388.3539 | J15: =SUM(J9:J14) -> 0 | K15: =SUM(K9:K14) -> 0 | L15: =SUM(L9:L14) -> 0 | M15: =SUM(M9:M14) -> 0
C16: Vorräte | D16: Inventories | F16: ='Balance Sheet (Annual Report)'!E33/1000 -> 1953.4011 | G16: =SUMIF('Trial Balance (Susa)'!D:D,"*"&$P16&"*",'Trial Balance (Susa)'!G:G)/1000 -> 2652.1087 | H16: =SUMIF('Trial Balance (Susa)'!D:D,"*"&$P16&"*",'Trial Balance (Susa)'!H:H)/1000 -> 3855.8836 | I16: =SUMIF('Trial Balance (Susa)'!D:D,"*"&$P16&"*",'Trial Balance (Susa)'!I:I)/1000 -> 2912.6866 | P16: /working capital/inventory
C17: Forderungen aus LuL | D17: Trade receivables | F17: ='Balance Sheet (Annual Report)'!E37/1000 -> 1780.6561 | G17: =SUMIF('Trial Balance (Susa)'!D:D,"*"&$P17&"*",'Trial Balance (Susa)'!G:G)/1000 -> 1586.3678 | H17: =SUMIF('Trial Balance (Susa)'!D:D,"*"&$P17&"*",'Trial Balance (Susa)'!H:H)/1000 -> 1988.8014 | I17: =SUMIF('Trial Balance (Susa)'!D:D,"*"&$P17&"*",'Trial Balance (Susa)'!I:I)/1000 -> 1415.6542 | P17: /working capital/all trade receivables
C18: Verbindlichkeiten aus LuL | D18: Trade payables | F18: =-'Balance Sheet (Annual Report)'!E84/1000 -> -752.85966 | G18: =SUMIF('Trial Balance (Susa)'!D:D,"*"&$P18&"*",'Trial Balance (Susa)'!G:G)/1000-G19 -> -848.28356 | H18: =SUMIF('Trial Balance (Susa)'!D:D,"*"&$P18&"*",'Trial Balance (Susa)'!H:H)/1000-H19 -> -1220.438 | I18: =SUMIF('Trial Balance (Susa)'!D:D,"*"&$P18&"*",'Trial Balance (Susa)'!I:I)/1000-I26 -> -243.48974 | P18: /working capital/all trade payables
C19: Erhaltene Anzahlungen | D19: Advance payments received | F19: =-'Balance Sheet (Annual Report)'!E82/1000 -> -50 | G19: =SUMIF('Trial Balance (Susa)'!D:D,"*"&$P19&"*",'Trial Balance (Susa)'!G:G)/1000 -> -50 | H19: =SUMIF('Trial Balance (Susa)'!D:D,"*"&$P19&"*",'Trial Balance (Susa)'!H:H)/1000 -> -50 | I19: =SUMIF('Trial Balance (Susa)'!D:D,"*"&$P19&"*",'Trial Balance (Susa)'!I:I)/1000 -> 0 | P19: /working capital/all trade payables/advances received on orders
C20: Dummy 1 | D20: Dummy 1
C21: Dummy 2 | D21: Dummy 2
C22: Dummy 3 | D22: Dummy 3
C23: Trade Working Capital | D23: Trade working capital | E23: =SUM(E16:E22) -> 0 | F23: =SUM(F16:F22) -> 2931.1975 | G23: =SUM(G16:G22) -> 3340.1929 | H23: =SUM(H16:H22) -> 4574.247 | I23: =SUM(I16:I22) -> 4084.851 | J23: =SUM(J16:J22) -> 0 | K23: =SUM(K16:K22) -> 0 | L23: =SUM(L16:L22) -> 0 | M23: =SUM(M16:M22) -> 0
C24: Sonstige Vermögensgegenstände | D24: Other assets | F24: ='Balance Sheet (Annual Report)'!E47/1000 -> 33.1297 | G24: =SUMIF('Trial Balance (Susa)'!D:D,"*"&$P24&"*",'Trial Balance (Susa)'!G:G)/1000 -> 296.51486 | H24: =SUMIF('Trial Balance (Susa)'!D:D,"*"&$P24&"*",'Trial Balance (Susa)'!H:H)/1000 -> 313.58526 | I24: =SUMIF('Trial Balance (Susa)'!D:D,"*"&$P24&"*",'Trial Balance (Susa)'!I:I)/1000 -> 309.09184 | P24: /working capital/other working capital/other current assets
C25: Aktive Rechnungsabgrenzungsposten | D25: Prepaid expenses | F25: ='Balance Sheet (Annual Report)'!E60/1000 -> 30.21821 | G25: =SUMIF('Trial Balance (Susa)'!D:D,"*"&$P25&"*",'Trial Balance (Susa)'!G:G)/1000 -> 65.90396 | H25: =SUMIF('Trial Balance (Susa)'!D:D,"*"&$P25&"*",'Trial Balance (Susa)'!H:H)/1000 -> 62.92786 | I25: =SUMIF('Trial Balance (Susa)'!D:D,"*"&$P25&"*",'Trial Balance (Susa)'!I:I)/1000 -> 51.30145 | P25: /working capital/other working capital/prepaid expenses
C26: Geleistete Anzahlung | D26: Receivables from affiliated/ participating companies | F26: 0 | G26: 0 | H26: 0 | I26: =('Dez25 Kreditoren'!I55+'Dez25 Kreditoren'!I56)/1000 -> 180.945
C27: Dummy 2
C28: Dummy 2 | D28: Dummy 2
C29: Dummy 3 | D29: Dummy 3
C30: Sonstige Aktiva | D30: Other assets | E30: =SUM(E24:E29) -> 0 | F30: =SUM(F24:F29) -> 63.34791 | G30: =SUM(G24:G29) -> 362.41882 | H30: =SUM(H24:H29) -> 376.51312 | I30: =SUM(I24:I29) -> 541.33829 | J30: =SUM(J24:J29) -> 0 | K30: =SUM(K24:K29) -> 0 | L30: =SUM(L24:L29) -> 0 | M30: =SUM(M24:M29) -> 0
C31: Sonstige Rückstellungen | D31: Other provisions | F31: =-'Balance Sheet (Annual Report)'!E79/1000 -> -527.64378 | G31: =SUMIF('Trial Balance (Susa)'!D:D,"*"&$P31&"*",'Trial Balance (Susa)'!G:G)/1000 -> -424.9074 | H31: =SUMIF('Trial Balance (Susa)'!D:D,"*"&$P31&"*",'Trial Balance (Susa)'!H:H)/1000 -> -228.40295 | I31: =SUMIF('Trial Balance (Susa)'!D:D,"*"&$P31&"*",'Trial Balance (Susa)'!I:I)/1000 -> -428.27366 | P31: /working capital/other working capital/other provisions
C32: Sonstige Verbindlichkeiten | D32: Other liabilities | F32: =-'Balance Sheet (Annual Report)'!E109/1000 -> -448.46014 | G32: =SUMIF('Trial Balance (Susa)'!D:D,"*"&$P32&"*",'Trial Balance (Susa)'!G:G)/1000 -> -290.29441 | H32: =SUMIF('Trial Balance (Susa)'!D:D,"*"&$P32&"*",'Trial Balance (Susa)'!H:H)/1000 -> -429.13633 | I32: =SUMIF('Trial Balance (Susa)'!D:D,"*"&$P32&"*",'Trial Balance (Susa)'!I:I)/1000 -> -231.74114 | P32: /working capital/other working capital/other current liabilities
C33: Dummy 1 | D33: Tax provisions | G33: =SUMIF('Trial Balance (Susa)'!D:D,"*"&$P33&"*",'Trial Balance (Susa)'!G:G)/1000 -> 0 | H33: =SUMIF('Trial Balance (Susa)'!D:D,"*"&$P33&"*",'Trial Balance (Susa)'!H:H)/1000 -> 0 | I33: =SUMIF('Trial Balance (Susa)'!D:D,"*"&$P33&"*",'Trial Balance (Susa)'!J:J)/1000 -> 0 | P33: /working capital/other working capital/tax provisions
C34: Dummy 1 | D34: Liabilities to affiliated/ participating companies | G34: =SUMIF('Trial Balance (Susa)'!D:D,"*"&$P34&"*",'Trial Balance (Susa)'!G:G)/1000 -> 0 | H34: =SUMIF('Trial Balance (Susa)'!D:D,"*"&$P34&"*",'Trial Balance (Susa)'!H:H)/1000 -> 0 | I34: =SUMIF('Trial Balance (Susa)'!D:D,"*"&$P34&"*",'Trial Balance (Susa)'!J:J)/1000 -> 0 | P34: /working capital/other working capital/liabilities to affiliated companies
C35: Dummy 1 | D35: Liabilities to shareholders | G35: =SUMIF('Trial Balance (Susa)'!D:D,"*"&$P35&"*",'Trial Balance (Susa)'!G:G)/1000 -> 0 | H35: =SUMIF('Trial Balance (Susa)'!D:D,"*"&$P35&"*",'Trial Balance (Susa)'!H:H)/1000 -> 0 | I35: =SUMIF('Trial Balance (Susa)'!D:D,"*"&$P35&"*",'Trial Balance (Susa)'!J:J)/1000 -> 0 | P35: /working capital/other working capital/liabilities to shareholders
C36: Dummy 1 | D36: Deferred income | P36: /working capital/other working capital/deferred income
C37: Dummy 1 | D37: Dummy 1
C38: Dummy 2 | D38: Dummy 2
C39: Dummy 3 | D39: Dummy 3
C40: Sonstige Passiva | D40: Other liabilities | E40: =SUM(E31:E39) -> 0 | F40: =SUM(F31:F39) -> -976.10392 | G40: =SUM(G31:G39) -> -715.20181 | H40: =SUM(H31:H39) -> -657.53928 | I40: =SUM(I31:I39) -> -660.0148 | J40: =SUM(J31:J39) -> 0 | K40: =SUM(K31:K39) -> 0 | L40: =SUM(L31:L39) -> 0 | M40: =SUM(M31:M39) -> 0
C41: Other Working Capital | D41: Other working capital | E41: =E40+E30 -> 0 | F41: =F40+F30 -> -912.75601 | G41: =G40+G30 -> -352.78299 | H41: =H40+H30 -> -281.02616 | I41: =I40+I30 -> -118.67651 | J41: =J40+J30 -> 0 | K41: =K40+K30 -> 0 | L41: =L40+L30 -> 0 | M41: =M40+M30 -> 0
C42: Net Working Capital | D42: Net working capital | E42: =E41+E23 -> 0 | F42: =F41+F23 -> 2018.4415 | G42: =G41+G23 -> 2987.4099 | H42: =H41+H23 -> 4293.2208 | I42: =I41+I23 -> 3966.1745 | J42: =J41+J23 -> 0 | K42: =K41+K23 -> 0 | L42: =L41+L23 -> 0 | M42: =M41+M23 -> 0
C43: Liquide Mittel | D43: Cash | F43: ='Balance Sheet (Annual Report)'!E57/1000 -> 3008.3487 | G43: =SUMIF('Trial Balance (Susa)'!D:D,"*"&$P43&"*",'Trial Balance (Susa)'!G:G)/1000 -> 2715.5673 | H43: =SUMIF('Trial Balance (Susa)'!D:D,"*"&$P43&"*",'Trial Balance (Susa)'!H:H)/1000 -> 1004.0608 | I43: =SUMIF('Trial Balance (Susa)'!D:D,"*"&$P43&"*",'Trial Balance (Susa)'!I:I)/1000 -> 2026.2807 | P43: /net debt/cash and cash equivalent
C44: Verbindlichkeiten ggü.Kreditinstituten | D44: Liabilities to banks | F44: 0 | G44: =SUMIF('Trial Balance (Susa)'!D:D,"*"&$P44&"*",'Trial Balance (Susa)'!G:G)/1000 -> 0 | H44: =SUMIF('Trial Balance (Susa)'!D:D,"*"&$P44&"*",'Trial Balance (Susa)'!H:H)/1000 -> 0 | I44: =SUMIF('Trial Balance (Susa)'!D:D,"*"&$P44&"*",'Trial Balance (Susa)'!I:I)/1000 -> -19.425 | P44: /net debt/liabilities to credit institutions
...

Sheet Lead CF
C4: =Cockpit!$C$4 -> Projekt Namur | E4: =Cockpit!C33 -> 44561 | F4: =Cockpit!D33 -> 44926 | G4: =Cockpit!E33 -> 45291 | H4: =Cockpit!F33 -> 45657 | I4: =Cockpit!G33 -> 46022 | J4: =Cockpit!H33 -> 46022 | K4: =Cockpit!I33 -> 46022 | L4: =Cockpit!J33 -> 46387 | ... N4: =Cockpit!L33 -> 47118 | P4: Bilanzveränderungen manuell zu ergänzen
C5: ="in T"&Cockpit!$C$5 -> in TEUR | E5: IST | F5: IST | G5: IST | H5: IST | I5: =Cockpit!G34 -> IST | J5: IST | K5: =Cockpit!I34 -> Plan | L5: =Cockpit!J34 -> Plan | M5: =Cockpit!K34 -> Plan | N5: =Cockpit!L34 -> Plan
D6: =Cockpit!$C$4 -> Projekt Namur | E6: =Cockpit!C33 -> 44561 | F6: =Cockpit!D33 -> 44926 | G6: =Cockpit!E33 -> 45291 | H6: =Cockpit!F33 -> 45657 | I6: =Cockpit!G33 -> 46022 | J6: =Cockpit!H33 -> 46022 | K6: =Cockpit!I33 -> 46022 | L6: =Cockpit!J33 -> 46387 | ... N6: =Cockpit!L33 -> 47118 | P6: Bilanzveränderungen manuell zu ergänzen
D7: ="in k"&Cockpit!$C$5 -> in kEUR | E7: =Cockpit!D34 -> IST | F7: =Cockpit!D34 -> IST | G7: =Cockpit!E34 -> IST | H7: =Cockpit!F34 -> IST | I7: =Cockpit!G34 -> IST | J7: =Cockpit!H34 -> YTD | K7: =Cockpit!I34 -> Plan | L7: =Cockpit!J34 -> Plan | M7: =Cockpit!K34 -> Plan | N7: =Cockpit!L34 -> Plan
C9: ='Lead PL'!C43 -> EBITDA | D9: ='Lead PL'!D43 -> EBITDA | F9: ='Lead PL'!F43 -> -4386.7022 | G9: ='Lead PL'!G43 -> -6491.3424 | H9: ='Lead PL'!H43 -> -6637.5466 | I9: ='Lead PL'!I43 -> -6045.3006 | J9: ='Lead PL'!I43 -> -6045.3006 | K9: ='Lead PL'!K43 -> 0 | L9: ='Lead PL'!L43 -> 0 | M9: ='Lead PL'!M43 -> 0 | N9: ='Lead PL'!N43 -> 0
C10: ='Lead PL'!C57 -> Ertragssteuern | D10: ='Lead PL'!D57 -> Income taxes | F10: ='Lead PL'!F57 -> -898.38628 | G10: ='Lead PL'!G57 -> -390.61759 | H10: ='Lead PL'!H57 -> -442.12161 | I10: ='Lead PL'!I57 -> -333.75368 | J10: ='Lead PL'!I57 -> -333.75368 | K10: ='Lead PL'!K58 -> 0 | L10: ='Lead PL'!L58 -> 0 | M10: ='Lead PL'!M58 -> 0 | N10: ='Lead PL'!N58 -> 0
C11: ='Lead PL'!C58 -> Sonstige Steuern | D11: ='Lead PL'!D58 -> Other taxes | F11: ='Lead PL'!F58 -> -3.077 | G11: ='Lead PL'!G58 -> -2.922 | H11: ='Lead PL'!H58 -> -3.002 | I11: ='Lead PL'!I58 -> -2.254 | J11: ='Lead PL'!I58 -> -2.254 | K11: ='Lead PL'!K57 -> 0 | L11: ='Lead PL'!L57 -> 0 | M11: ='Lead PL'!M57 -> 0 | N11: ='Lead PL'!N57 -> 0
C12: ="∆ "&'Lead NA'!C45 -> ∆ Pensionsrückstellungen | F12: =-'Lead NA'!F45+'Lead NA'!E45 -> 201.476 | G12: =-'Lead NA'!G45+'Lead NA'!F45 -> -9.374 | H12: =-'Lead NA'!H45+'Lead NA'!G45 -> -9.699 | I12: =-NA_monthly!AX46+NA_monthly!AL46 -> -9.699 | J12: =-'Lead NA'!I45+'Lead NA'!H45 -> -10.66
C13: ="∆ "&'Lead NA'!C46 -> ∆ Steuerrückstellungen | F13: =-'Lead NA'!F46+'Lead NA'!E46 -> 224.92819 | G13: =-'Lead NA'!G46+'Lead NA'!F46 -> 0 | H13: =-'Lead NA'!H46+'Lead NA'!G46 -> -224.92819 | I13: =-NA_monthly!AX47+NA_monthly!AL47 -> -15.44608 | J13: =-'Lead NA'!I46+'Lead NA'!H46 -> 0
C14: ="∆ "&'Lead NA'!C50 -> ∆ Passive latente Steuern | G14: =-'Lead NA'!G50+'Lead NA'!F50 -> 0 | H14: =-'Lead NA'!H50+'Lead NA'!G50 -> 48.876 | I14: =-NA_monthly!AX51+NA_monthly!AL51 -> 48.876 | J14: =-'Lead NA'!I50+'Lead NA'!H50 -> 149.46
C16: ="∆ "&'Lead NA'!C16 -> ∆ Vorräte | D16: ="∆ "&'Lead NA'!D16 -> ∆ Inventories | F16: =-'Lead NA'!F16+'Lead NA'!E16 -> -1953.4011 | G16: =-'Lead NA'!G16+'Lead NA'!F16 -> -698.70757 | H16: =-'Lead NA'!H16+'Lead NA'!G16 -> -1203.775 | I16: =-NA_monthly!AX16+NA_monthly!AL16 -> -1180.3231 | J16: =-'Lead NA'!I16+'Lead NA'!H16 -> 943.19708 | K16: =-'Lead NA'!J16+'Lead NA'!H16 -> 3855.8836 | L16: =-'Lead NA'!K16+'Lead NA'!J16 -> 0 | M16: =-'Lead NA'!L16+'Lead NA'!K16 -> 0 | N16: =-'Lead NA'!M16+'Lead NA'!L16 -> 0
C17: ="∆ "&'Lead NA'!C17 -> ∆ Forderungen aus LuL | D17: ="∆ "&'Lead NA'!D17 -> ∆ Trade receivables | F17: =-'Lead NA'!F17+'Lead NA'!E17 -> -1780.6561 | G17: =-'Lead NA'!G17+'Lead NA'!F17 -> 194.28828 | H17: =-'Lead NA'!H17+'Lead NA'!G17 -> -402.43357 | I17: =-NA_monthly!AX17+NA_monthly!AL17 -> -60.55489 | J17: =-'Lead NA'!I17+'Lead NA'!H17 -> 573.14715 | K17: =-'Lead NA'!J17+'Lead NA'!H17 -> 1988.8014 | L17: =-'Lead NA'!K17+'Lead NA'!J17 -> 0 | M17: =-'Lead NA'!L17+'Lead NA'!K17 -> 0 | N17: =-'Lead NA'!M17+'Lead NA'!L17 -> 0
C18: ="∆ "&'Lead NA'!C18 -> ∆ Verbindlichkeiten aus LuL | D18: ="∆ "&'Lead NA'!D18 -> ∆ Trade payables | F18: =-'Lead NA'!F18+'Lead NA'!E18 -> 752.85966 | G18: =-'Lead NA'!G18+'Lead NA'!F18 -> 95.4239 | H18: =-'Lead NA'!H18+'Lead NA'!G18 -> 372.15445 | I18: =-NA_monthly!AX18+NA_monthly!AL18 -> -945.14974 | J18: =-'Lead NA'!I18+'Lead NA'!H18 -> -976.94827 | K18: =-'Lead NA'!J18+'Lead NA'!H18 -> -1220.438 | L18: =-'Lead NA'!K18+'Lead NA'!J18 -> 0 | M18: =-'Lead NA'!L18+'Lead NA'!K18 -> 0 | N18: =-'Lead NA'!M18+'Lead NA'!L18 -> 0
C19: ="∆ "&'Lead NA'!C19 -> ∆ Erhaltene Anzahlungen | D19: ="∆ "&'Lead NA'!D19 -> ∆ Advance payments received | F19: =-'Lead NA'!F19+'Lead NA'!E19 -> 50 | G19: =-'Lead NA'!G19+'Lead NA'!F19 -> 0 | H19: =-'Lead NA'!H19+'Lead NA'!G19 -> 0 | I19: =-NA_monthly!AX19+NA_monthly!AL19 -> -50 | J19: =-'Lead NA'!I19+'Lead NA'!H19 -> -50
C20: ="∆ "&'Lead NA'!C20 -> ∆ Dummy 1 | D20: ="∆ "&'Lead NA'!D20 -> ∆ Dummy 1 | F20: =-'Lead NA'!F20+'Lead NA'!E20 -> 0 | G20: =-'Lead NA'!G20+'Lead NA'!F20 -> 0 | H20: =-'Lead NA'!H20+'Lead NA'!G20 -> 0 | J20: =-'Lead NA'!I20+'Lead NA'!H20 -> 0 | K20: =-'Lead NA'!J20+'Lead NA'!H20 -> 0 | L20: =-'Lead NA'!K20+'Lead NA'!J20 -> 0 | M20: =-'Lead NA'!L20+'Lead NA'!K20 -> 0 | N20: =-'Lead NA'!M20+'Lead NA'!L20 -> 0
C21: ="∆ "&'Lead NA'!C21 -> ∆ Dummy 2 | D21: ="∆ "&'Lead NA'!D21 -> ∆ Dummy 2 | F21: =-'Lead NA'!F21+'Lead NA'!E21 -> 0 | G21: =-'Lead NA'!G21+'Lead NA'!F21 -> 0 | H21: =-'Lead NA'!H21+'Lead NA'!G21 -> 0 | J21: =-'Lead NA'!I21+'Lead NA'!H21 -> 0 | K21: =-'Lead NA'!J21+'Lead NA'!H21 -> 0 | L21: =-'Lead NA'!K21+'Lead NA'!J21 -> 0 | M21: =-'Lead NA'!L21+'Lead NA'!K21 -> 0 | N21: =-'Lead NA'!M21+'Lead NA'!L21 -> 0
C22: ="∆ "&'Lead NA'!C22 -> ∆ Dummy 3 | D22: ="∆ "&'Lead NA'!D22 -> ∆ Dummy 3 | F22: =-'Lead NA'!F22+'Lead NA'!E22 -> 0 | G22: =-'Lead NA'!G22+'Lead NA'!F22 -> 0 | H22: =-'Lead NA'!H22+'Lead NA'!G22 -> 0 | J22: =-'Lead NA'!I22+'Lead NA'!H22 -> 0 | K22: =-'Lead NA'!J22+'Lead NA'!H22 -> 0 | L22: =-'Lead NA'!K22+'Lead NA'!J22 -> 0 | M22: =-'Lead NA'!L22+'Lead NA'!K22 -> 0 | N22: =-'Lead NA'!M22+'Lead NA'!L22 -> 0
C23: ="∆ "&'Lead NA'!C23 -> ∆ Trade Working Capital | D23: ="∆ "&'Lead NA'!D23 -> ∆ Trade working capital | F23: =SUM(F16:F22) -> -2931.1975 | G23: =SUM(G16:G22) -> -408.99539 | H23: =SUM(H16:H22) -> -1234.0541 | I23: =SUM(I16:I22) -> -2236.0277 | J23: =SUM(J16:J22) -> 489.39596 | K23: =SUM(K16:K22) -> 4624.247 | L23: =SUM(L16:L22) -> 0 | M23: =SUM(M16:M22) -> 0 | N23: =SUM(N16:N22) -> 0
C24: ="∆ "&'Lead NA'!C24 -> ∆ Sonstige Vermögensgegenstände | D24: ="∆ "&'Lead NA'!D24 -> ∆ Other assets | F24: =-'Lead NA'!F24+'Lead NA'!E24 -> -33.1297 | G24: =-'Lead NA'!G24+'Lead NA'!F24 -> -263.38516 | H24: =-'Lead NA'!H24+'Lead NA'!G24 -> -17.0704 | I24: =-NA_monthly!AX24+NA_monthly!AL24 -> 110.73111 | J24: =-'Lead NA'!I24+'Lead NA'!H24 -> 4.49342 | K24: =-'Lead NA'!J24+'Lead NA'!H24 -> 313.58526 | L24: =-'Lead NA'!K24+'Lead NA'!J24 -> 0 | M24: =-'Lead NA'!L24+'Lead NA'!K24 -> 0 | N24: =-'Lead NA'!M24+'Lead NA'!L24 -> 0
C25: ="∆ "&'Lead NA'!C25 -> ∆ Aktive Rechnungsabgrenzungsposten | D25: ="∆ "&'Lead NA'!D25 -> ∆ Prepaid expenses | F25: =-'Lead NA'!F25+'Lead NA'!E25 -> -30.21821 | G25: =-'Lead NA'!G25+'Lead NA'!F25 -> -35.68575 | H25: =-'Lead NA'!H25+'Lead NA'!G25 -> 2.9761 | I25: =-NA_monthly!AX25+NA_monthly!AL25 -> -10.35157 | J25: =-'Lead NA'!I25+'Lead NA'!H25 -> 11.62641 | K25: =-'Lead NA'!J25+'Lead NA'!H25 -> 62.92786 | L25: =-'Lead NA'!K25+'Lead NA'!J25 -> 0 | M25: =-'Lead NA'!L25+'Lead NA'!K25 -> 0 | N25: =-'Lead NA'!M25+'Lead NA'!L25 -> 0
C26: ="∆ "&'Lead NA'!C26 -> ∆ Geleistete Anzahlung | D26: ="∆ "&'Lead NA'!D26 -> ∆ Receivables from affiliated/ participating companies | F26: =-'Lead NA'!F26+'Lead NA'!E26 -> 0 | G26: =-'Lead NA'!G26+'Lead NA'!F26 -> 0 | H26: =-'Lead NA'!H26+'Lead NA'!G26 -> 0 | J26: =-'Lead NA'!I26+'Lead NA'!H26 -> -180.945
C27: ="∆ "&'Lead NA'!C27 -> ∆ Dummy 2 | D27: ="∆ "&'Lead NA'!D27 -> ∆ | F27: =-'Lead NA'!F27+'Lead NA'!E27 -> 0 | G27: =-'Lead NA'!G27+'Lead NA'!F27 -> 0 | H27: =-'Lead NA'!H27+'Lead NA'!G27 -> 0 | J27: =-'Lead NA'!I27+'Lead NA'!H27 -> 0 | K27: =-'Lead NA'!J27+'Lead NA'!H27 -> 0 | L27: =-'Lead NA'!K27+'Lead NA'!J27 -> 0 | M27: =-'Lead NA'!L27+'Lead NA'!K27 -> 0 | N27: =-'Lead NA'!M27+'Lead NA'!L27 -> 0
C28: ="∆ "&'Lead NA'!C28 -> ∆ Dummy 2 | D28: ="∆ "&'Lead NA'!D28 -> ∆ Dummy 2 | F28: =-'Lead NA'!F28+'Lead NA'!E28 -> 0 | G28: =-'Lead NA'!G28+'Lead NA'!F28 -> 0 | H28: =-'Lead NA'!H28+'Lead NA'!G28 -> 0 | J28: =-'Lead NA'!I28+'Lead NA'!H28 -> 0 | K28: =-'Lead NA'!J28+'Lead NA'!H28 -> 0 | L28: =-'Lead NA'!K28+'Lead NA'!J28 -> 0 | M28: =-'Lead NA'!L28+'Lead NA'!K28 -> 0 | N28: =-'Lead NA'!M28+'Lead NA'!L28 -> 0
C29: ="∆ "&'Lead NA'!C29 -> ∆ Dummy 3 | D29: ="∆ "&'Lead NA'!D29 -> ∆ Dummy 3 | F29: =-'Lead NA'!F29+'Lead NA'!E29 -> 0 | G29: =-'Lead NA'!G29+'Lead NA'!F29 -> 0 | H29: =-'Lead NA'!H29+'Lead NA'!G29 -> 0 | J29: =-'Lead NA'!I29+'Lead NA'!H29 -> 0 | K29: =-'Lead NA'!J29+'Lead NA'!H29 -> 0 | L29: =-'Lead NA'!K29+'Lead NA'!J29 -> 0 | M29: =-'Lead NA'!L29+'Lead NA'!K29 -> 0 | N29: =-'Lead NA'!M29+'Lead NA'!L29 -> 0
C30: ="∆ "&'Lead NA'!C31 -> ∆ Sonstige Rückstellungen | D30: ="∆ "&'Lead NA'!D31 -> ∆ Other provisions | F30: =-'Lead NA'!F31+'Lead NA'!E31 -> 527.64378 | G30: =-'Lead NA'!G31+'Lead NA'!F31 -> -102.73638 | H30: =-'Lead NA'!H31+'Lead NA'!G31 -> -196.50445 | I30: =-NA_monthly!AX32+NA_monthly!AL32 -> 71.64589 | J30: =-'Lead NA'!I31+'Lead NA'!H31 -> 199.87071 | K30: =-'Lead NA'!J31+'Lead NA'!H31 -> -228.40295 | L30: =-'Lead NA'!K31+'Lead NA'!J31 -> 0 | M30: =-'Lead NA'!L31+'Lead NA'!K31 -> 0 | N30: =-'Lead NA'!M31+'Lead NA'!L31 -> 0
C31: ="∆ "&'Lead NA'!C32 -> ∆ Sonstige Verbindlichkeiten | D31: ="∆ "&'Lead NA'!D32 -> ∆ Other liabilities | F31: =-'Lead NA'!F32+'Lead NA'!E32 -> 448.46014 | G31: =-'Lead NA'!G32+'Lead NA'!F32 -> -158.16573 | H31: =-'Lead NA'!H32+'Lead NA'!G32 -> 138.84192 | I31: =-NA_monthly!AX33+NA_monthly!AL33 -> -103.94465 | J31: =-'Lead NA'!I32+'Lead NA'!H32 -> -197.39519 | K31: =-'Lead NA'!J32+'Lead NA'!H32 -> -429.13633 | L31: =-'Lead NA'!K32+'Lead NA'!J32 -> 0 | M31: =-'Lead NA'!L32+'Lead NA'!K32 -> 0 | N31: =-'Lead NA'!M32+'Lead NA'!L32 -> 0
C32: ="∆ "&'Lead NA'!C33 -> ∆ Dummy 1 | D32: ="∆ "&'Lead NA'!D33 -> ∆ Tax provisions | F32: =-'Lead NA'!F33+'Lead NA'!E33 -> 0 | G32: =-'Lead NA'!G33+'Lead NA'!F33 -> 0 | H32: =-'Lead NA'!H33+'Lead NA'!G33 -> 0 | J32: =-'Lead NA'!I33+'Lead NA'!H33 -> 0
C33: ="∆ "&'Lead NA'!C34 -> ∆ Dummy 1 | D33: ="∆ "&'Lead NA'!D34 -> ∆ Liabilities to affiliated/ participating companies | F33: =-'Lead NA'!F34+'Lead NA'!E34 -> 0 | G33: =-'Lead NA'!G34+'Lead NA'!F34 -> 0 | H33: =-'Lead NA'!H34+'Lead NA'!G34 -> 0 | J33: =-'Lead NA'!I34+'Lead NA'!H34 -> 0 | K33: =-'Lead NA'!J34+'Lead NA'!H34 -> 0 | L33: =-'Lead NA'!K34+'Lead NA'!J34 -> 0 | M33: =-'Lead NA'!L34+'Lead NA'!K34 -> 0 | N33: =-'Lead NA'!M34+'Lead NA'!L34 -> 0
C34: ="∆ "&'Lead NA'!C35 -> ∆ Dummy 1 | D34: ="∆ "&'Lead NA'!D35 -> ∆ Liabilities to shareholders | F34: =-'Lead NA'!F35+'Lead NA'!E35 -> 0 | G34: =-'Lead NA'!G35+'Lead NA'!F35 -> 0 | H34: =-'Lead NA'!H35+'Lead NA'!G35 -> 0 | J34: =-'Lead NA'!I35+'Lead NA'!H35 -> 0 | K34: =-'Lead NA'!J35+'Lead NA'!H35 -> 0 | L34: =-'Lead NA'!K35+'Lead NA'!J35 -> 0 | M34: =-'Lead NA'!L35+'Lead NA'!K35 -> 0 | N34: =-'Lead NA'!M35+'Lead NA'!L35 -> 0
C35: ="∆ "&'Lead NA'!C36 -> ∆ Dummy 1 | D35: ="∆ "&'Lead NA'!D36 -> ∆ Deferred income | F35: =-'Lead NA'!F36+'Lead NA'!E36 -> 0 | G35: =-'Lead NA'!G36+'Lead NA'!F36 -> 0 | H35: =-'Lead NA'!H36+'Lead NA'!G36 -> 0 | J35: =-'Lead NA'!I36+'Lead NA'!H36 -> 0
C36: ="∆ "&'Lead NA'!C37 -> ∆ Dummy 1 | D36: ="∆ "&'Lead NA'!D37 -> ∆ Dummy 1 | F36: =-'Lead NA'!F37+'Lead NA'!E37 -> 0 | G36: =-'Lead NA'!G37+'Lead NA'!F37 -> 0 | H36: =-'Lead NA'!H37+'Lead NA'!G37 -> 0 | J36: =-'Lead NA'!I37+'Lead NA'!H37 -> 0
C37: ="∆ "&'Lead NA'!C38 -> ∆ Dummy 2 | D37: ="∆ "&'Lead NA'!D38 -> ∆ Dummy 2 | F37: =-'Lead NA'!F38+'Lead NA'!E38 -> 0 | G37: =-'Lead NA'!G38+'Lead NA'!F38 -> 0 | H37: =-'Lead NA'!H38+'Lead NA'!G38 -> 0 | J37: =-'Lead NA'!I38+'Lead NA'!H38 -> 0
C38: ="∆ "&'Lead NA'!C39 -> ∆ Dummy 3 | D38: ="∆ "&'Lead NA'!D39 -> ∆ Dummy 3 | F38: =-'Lead NA'!F39+'Lead NA'!E39 -> 0 | G38: =-'Lead NA'!G39+'Lead NA'!F39 -> 0 | H38: =-'Lead NA'!H39+'Lead NA'!G39 -> 0 | J38: =-'Lead NA'!I39+'Lead NA'!H39 -> 0 | K38: =-'Lead NA'!J39+'Lead NA'!H39 -> 0 | L38: =-'Lead NA'!K39+'Lead NA'!J39 -> 0 | M38: =-'Lead NA'!L39+'Lead NA'!K39 -> 0 | N38: =-'Lead NA'!M39+'Lead NA'!L39 -> 0
C39: ="∆ "&'Lead NA'!C41 -> ∆ Other Working Capital | D39: ="∆ "&'Lead NA'!D41 -> ∆ Other working capital | F39: =SUM(F24:F38) -> 912.75601 | G39: =SUM(G24:G38) -> -559.97302 | H39: =SUM(H24:H38) -> -71.75683 | I39: =SUM(I24:I38) -> 68.08078 | J39: =SUM(J24:J38) -> -162.34965 | K39: =SUM(K24:K38) -> -281.02616 | L39: =SUM(L24:L38) -> 0 | M39: =SUM(M24:M38) -> 0 | N39: =SUM(N24:N38) -> 0
C40: Operativer Cashflow | D40: Operating cash flow | F40: =F9+SUM(F10:F11)+F23+F39 -> -7306.6069 | G40: =G9+SUM(G10:G14)+G23+G39 -> -7863.2244 | H40: =H9+SUM(H10:H14)+H23+H39 -> -8574.2324 | I40: =I9+SUM(I10:I14)+I23+I39 -> -8525.5243 | J40: =J9+SUM(J10:J14)+J23+J39 -> -5915.462 | K40: =K9+SUM(K10:K11)+K23+K39 -> 4343.2208 | L40: =L9+SUM(L10:L11)+L23+L39 -> 0 | M40: =M9+SUM(M10:M11)+M23+M39 -> 0 | N40: =N9+SUM(N10:N11)+N23+N39 -> 0
C42: CAPEX | D42: Maintenance CAPEX | F42: =-('Lead NA'!F15-'Lead NA'!E15)+'Lead PL'!F44 -> -1549.2268 | G42: =-('Lead NA'!G15-'Lead NA'!F15)+'Lead PL'!G44 -> -31.71571 | H42: =-('Lead NA'!H15-'Lead NA'!G15)+'Lead PL'!H44 -> -520.92459 | I42: =-(NA_monthly!AX15-NA_monthly!AL15)+SUM(PL_monthly!AM35:AX35) -> -334.70818 | J42: =-('Lead NA'!I15-'Lead NA'!H15)+'Lead PL'!I44 -> -550.9706
C43: Dummy 1 | D43: Expansion CAPEX | P43: Check for information regarding maintenance/ expansion or change to generally "CAPEX"
C44: Dummy 1 | D44: Dummy 1
C45: Dummy 2 | D45: Dummy 2
C46: Dummy 3 | D46: Dummy 3
...

Sheet PL >>

Sheet PL_Top customer
C4: =Cockpit!$C$4 -> Projekt Namur | E4: =Cockpit!D33 -> 44926 | H4: =Cockpit!E33 -> 45291 | K4: =Cockpit!F33 -> 45657 | N4: =Cockpit!G33 -> 46022 | Q4: =Cockpit!H33 -> 46022
C5: ="in T"&Cockpit!$C$5 -> in TEUR | E5: # | F5: IST | H5: # | I5: IST | K5: # | L5: IST | N5: # | O5: LTM | Q5: # | R5: YTD
D6: =Cockpit!$C$4 -> Projekt Namur | E6: =Cockpit!D33 -> 44926 | H6: =Cockpit!E33 -> 45291 | K6: =Cockpit!F33 -> 45657 | N6: =Cockpit!G33 -> 46022 | Q6: =Cockpit!H33 -> 46022
D7: ="in k"&Cockpit!$C$5 -> in kEUR | E7: # | F7: Act. | H7: # | I7: Act. | K7: # | L7: Act. | N7: # | O7: LTM | Q7: # | R7: YTD
C9: Top10 Kunden pro Geschäftsjahr* | D9: TOP10 customers per fiscal year*
C10: Kunde 1 | D10: Customer 1 | K10: 1 | T10: !ACHTUNG: TOP10 des jeweiligen Jahres* hellgrau/dunkelgrün (YTD) hinterlegen und #RANG ergänzen
C11: Kunde 2 | D11: Customer 2 | K11: 2 | T11: !ACHTUNG: Basis der TOP10 Ordnung in der Fußnote aktualisieren (Standard ist Gliederung nach LTM Umsätzen)
C12: Kunde 3 | D12: Customer 3 | K12: 3
C13: Kunde 4 | D13: Customer 4 | K13: 4
C14: Kunde 5 | D14: Customer 5 | K14: 5
C15: Kunde 6 | D15: Customer 6 | K15: 6
C16: Kunde 7 | D16: Customer 7 | K16: 7
C17: Kunde 8 | D17: Customer 8 | K17: 8
C18: Kunde 9 | D18: Customer 9 | K18: 9
C19: Kunde 10 | D19: Customer 10 | K19: 10
C20: Kunde 11 | D20: Customer 11
C21: Kunde 12 | D21: Customer 12
C22: Kunde 13 | D22: Customer 13
C23: Kunde 14 | D23: Customer 14
C24: Kunde 15 | D24: Customer 15
C25: Kunde 16 | D25: Customer 16
C26: Kunde 17 | D26: Customer 17
C27: Kunde 18 | D27: Customer 18
C28: Kunde 19 | D28: Customer 19
C29: Kunde 20 | D29: Customer 20
C30: Umsatzerlöse Top Kunden | D30: Revenues Top customers | F30: =SUM(F10:F29) -> 0 | I30: =SUM(I10:I29) -> 0 | L30: =SUM(L10:L29) -> 0 | O30: =SUM(O10:O29) -> 0 | R30: =SUM(R10:R29) -> 0
C31: Sonstige Umsatzerlöse | D31: Other Revenues | F31: =F32-F30 -> 16416.745 | I31: =I32-I30 -> 15515.821 | L31: =L32-L30 -> 17010.759 | O31: =O32-O30 -> 15235.918 | R31: =R32-R30 -> 0
C32: Gesamtleistung gesamt | D32: Total output | F32: ='Lead PL'!F24 -> 16416.745 | I32: ='Lead PL'!G24 -> 15515.821 | L32: ='Lead PL'!H24 -> 17010.759 | O32: ='Lead PL'!I24 -> 15235.918 | R32: ='Lead PL'!J24 -> 0
C34: Anteil Top1 Kunde | D34: Share Top1 customer | L34: =L10/L32 -> 0 | T34: !ACHTUNG: Anteil TOP Kunden jeweils nachziehen
C35: Anteil Top5 Kunden | D35: Share Top5 customers | L35: =(L14+L10+L13+L12+L11)/L32 -> 0
C36: Anteil Top10 Kunden | D36: Share Top10 customers | L36: =(L13+L12+L19+L11+L10+L15+L17+L16+L14+L18)/L32 -> 0
C38: *Top10 Kunden des jeweiligen Jahres markiert, Gliederung basiert auf den LTM Jan23 Umsätzen | D38: *Top10 customers per each fiscal year, order is based on LTM Jan23 revenues
C40: ="Quelle: "&Cockpit!$C$7 -> Quelle: Datenraum/ eigene Analysen | D40: ="Source: "&Cockpit!$C$8 -> Source: Virtual Data Room/ Company Information
C42: Gesamleistung lt. Lead PL | D42: Total output acc. to Lead PL | F42: ='Lead PL'!F24 -> 16416.745 | I42: ='Lead PL'!G24 -> 15515.821 | L42: ='Lead PL'!H24 -> 17010.759 | O42: ='Lead PL'!I24 -> 15235.918 | R42: ='Lead PL'!J24 -> 0
C43: Check | D43: Check | F43: =F32-F42 -> 0 | I43: =I32-I42 -> 0 | L43: =L32-L42 -> 0 | O43: =O32-O42 -> 0 | R43: =R32-R42 -> 0

Sheet PL_PEX
C1: Technische Zeile --> nicht löschen | D1: Technische Zeile --> nicht löschen | F1: =IFERROR(F4,F6) -> 44926 | G1: =IFERROR(G4,G6) -> 45291 | H1: =IFERROR(H4,H6) -> 45657 | I1: =IFERROR(I4,I6) -> 46022 | J1: =IFERROR(J4,J6) -> 46022 | K1: =IFERROR(K4,K6) -> 46022 | L1: =IFERROR(L4,L6) -> 46387 | M1: =IFERROR(M4,M6) -> 46752 | N1: =IFERROR(N4,N6) -> 47118
C4: =Cockpit!$C$4 -> Projekt Namur | F4: ='Lead PL'!F4 -> 44926 | G4: ='Lead PL'!G4 -> 45291 | H4: ='Lead PL'!H4 -> 45657 | I4: ='Lead PL'!I4 -> 46022 | J4: ='Lead PL'!J4 -> 46022 | K4: ='Lead PL'!K4 -> 46022 | L4: ='Lead PL'!L4 -> 46387 | M4: ='Lead PL'!M4 -> 46752 | N4: ='Lead PL'!N4 -> 47118 | P4: ='Lead PL'!P4 -> CAGR | Q4: ='Lead PL'!Q4 -> CAGR | T4: BT Kategorisierung | V4: Kommentar BT | Y4: Heinz Meise
C5: ="in T"&Cockpit!$C$5 -> in TEUR | F5: ='Lead PL'!F5 -> IST | G5: ='Lead PL'!G5 -> IST | H5: ='Lead PL'!H5 -> IST | I5: ='Lead PL'!I5 -> IST | J5: ='Lead PL'!I5 -> IST | K5: ='Lead PL'!K5 -> Plan | L5: ='Lead PL'!L5 -> Plan | M5: ='Lead PL'!M5 -> Plan | N5: ='Lead PL'!N5 -> Plan | P5: ='Lead PL'!P5 -> IST | Q5: ='Lead PL'!Q5 -> Plan
D6: =Cockpit!$C$4 -> Projekt Namur | F6: ='Lead PL'!F6 -> 44926 | G6: ='Lead PL'!G6 -> 45291 | H6: ='Lead PL'!H6 -> 45657 | I6: ='Lead PL'!I6 -> 46022 | J6: ='Lead PL'!J6 -> 46022 | K6: ='Lead PL'!K6 -> 46022 | L6: ='Lead PL'!L6 -> 46387 | M6: ='Lead PL'!M6 -> 46752 | N6: ='Lead PL'!N6 -> 47118 | P6: ='Lead PL'!P6 -> CAGR | Q6: ='Lead PL'!Q6 -> CAGR
D7: ="in k"&Cockpit!$C$5 -> in kEUR | F7: ='Lead PL'!F7 -> IST | G7: ='Lead PL'!G7 -> IST | H7: ='Lead PL'!H7 -> IST | I7: ='Lead PL'!I7 -> IST | J7: ='Lead PL'!J7 -> YTD | K7: ='Lead PL'!K7 -> Plan | L7: ='Lead PL'!L7 -> Plan | M7: ='Lead PL'!M7 -> Plan | N7: ='Lead PL'!N7 -> Plan | P7: ='Lead PL'!P7 -> IST | Q7: ='Lead PL'!Q7 -> Plan
C9: Geschäftsführergehalt | D9: Dummy 1 | F9: =G9 -> 228 | G9: =SUMIFS('Trial Balance (Susa)'!G:G,'Trial Balance (Susa)'!$E:$E,$T9)/1000 -> 228 | H9: =SUMIFS('Trial Balance (Susa)'!H:H,'Trial Balance (Susa)'!$E:$E,$T9)/1000 -> 290.50002 | I9: 353.00004 | J9: =SUMIFS('Trial Balance (Susa)'!I:I,'Trial Balance (Susa)'!$E:$E,$T9)/1000 -> 353.00004 | P9: =IFERROR(((H9/F9)^(1/(($H$1-$F$1)/365)))-1,"n/a") -> 0.1285835 | Q9: =IFERROR(((N9/H9)^(1/(($N$1-$H$1)/365)))-1,"n/a") -> -1 | T9: GF Gehalt | V9: Tantieme f. Henze wurde in 2024 und 2025 auf falsches Konto gebucht, manuell angepasst
C10: Tantieme Geschäftsführer | F10: =G10 -> 76 | G10: =SUMIFS('Trial Balance (Susa)'!G:G,'Trial Balance (Susa)'!$E:$E,$T10)/1000 -> 76 | H10: =SUMIFS('Trial Balance (Susa)'!H:H,'Trial Balance (Susa)'!$E:$E,$T10)/1000+SUMIFS('Trial Balance (Susa)'!H:H,'Trial Balance (Susa)'!$E:$E,$T14)/1000 -> 92.757 | I10: 353.00004 | J10: =SUMIFS('Trial Balance (Susa)'!I:I,'Trial Balance (Susa)'!$E:$E,$T10)/1000+SUMIFS('Trial Balance (Susa)'!I:I,'Trial Balance (Susa)'!$E:$E,$T14)/1000 -> 88.53 | T10: GF Tantieme
C11: GF Vergütung | F11: =SUM(F9:F10) -> 304 | G11: =SUM(G9:G10) -> 304 | H11: =SUM(H9:H10) -> 383.25702 | I11: =SUM(I9:I10) -> 706.00008 | J11: =SUM(J9:J10) -> 441.53004
